Workbook

Sheet Read me
A1: Gratifi: flight use cases
A2: Every thing a customer might want done with a flight, written as one row each, with what Gratifi does, the UI blocks it uses from the Gratifi UI kit, what the systems decide, and what changes by market.
A4: How a row is built
A5: Stage × Job × Constraint × Exception. The same job ("Book a return flight") appears once per constraint that changes the answer, and once per exception that changes the flow.
A6: Customer says is one real example; the agent is trained on many phrasings per row. Gratifi does is the answer shape. UI blocks name components in the kit. Rules are decided by systems, never by the model.
A8: Scoring (1 low to 5 high)
A9: Volume: how often customers ask. Value: revenue or loyalty impact. Risk: harm if wrong (money, rights, safety). Priority = Volume × Value ÷ Risk.
A11: Build waves (edit the blue cells to change them)
A12: Wave 1 needs priority of at least | B12: 6
A13: Wave 1 needs risk no higher than | B13: 2
A14: Rows with risk of at least this go to wave 3 (legal and human sign-off first) | B14: 4
A15: Core path (Y) rows are wave 1 whatever their score: a customer cannot book without them.
A16: Status
A17: • Scores are a first pass by Claude for discussion; the product team should re-score with real volumes from partner banks.
A18: • Compensation amounts are named only where set by law (UK261, EU261). For India (DGCA), Malaysia (MAVCOM), Singapore and UAE the rule is named and the amount must come from each bank's legal team.
A19: • Airlines in the kit are fictional. Market notes are prompts to check, not legal advice.
A20: • To add a use case: add a row at the bottom of "Use cases" and copy the Priority and Wave formulas down.

Sheet Summary
A1: Summary
A3: Stage | B3: Use cases | C3: Wave 1 | D3: Wave 2 | E3: Wave 3 | F3: Average priority
A4: Inspire | B4: =COUNTIF('Use cases'!$B$2:$B$119,A4) -> 8 | C4: =COUNTIFS('Use cases'!$B$2:$B$119,$A4,'Use cases'!$P$2:$P$119,1) -> 8 | D4: =COUNTIFS('Use cases'!$B$2:$B$119,$A4,'Use cases'!$P$2:$P$119,2) -> 0 | E4: =COUNTIFS('Use cases'!$B$2:$B$119,$A4,'Use cases'!$P$2:$P$119,3) -> 0 | F4: =IFERROR(ROUND(AVERAGEIF('Use cases'!$B$2:$B$119,A4,'Use cases'!$O$2:$O$119),1),0) -> 9.1
A5: Search | B5: =COUNTIF('Use cases'!$B$2:$B$119,A5) -> 18 | C5: =COUNTIFS('Use cases'!$B$2:$B$119,$A5,'Use cases'!$P$2:$P$119,1) -> 11 | D5: =COUNTIFS('Use cases'!$B$2:$B$119,$A5,'Use cases'!$P$2:$P$119,2) -> 7 | E5: =COUNTIFS('Use cases'!$B$2:$B$119,$A5,'Use cases'!$P$2:$P$119,3) -> 0 | F5: =IFERROR(ROUND(AVERAGEIF('Use cases'!$B$2:$B$119,A5,'Use cases'!$O$2:$O$119),1),0) -> 8.6
A6: Choose | B6: =COUNTIF('Use cases'!$B$2:$B$119,A6) -> 12 | C6: =COUNTIFS('Use cases'!$B$2:$B$119,$A6,'Use cases'!$P$2:$P$119,1) -> 3 | D6: =COUNTIFS('Use cases'!$B$2:$B$119,$A6,'Use cases'!$P$2:$P$119,2) -> 8 | E6: =COUNTIFS('Use cases'!$B$2:$B$119,$A6,'Use cases'!$P$2:$P$119,3) -> 1 | F6: =IFERROR(ROUND(AVERAGEIF('Use cases'!$B$2:$B$119,A6,'Use cases'!$O$2:$O$119),1),0) -> 5.1
A7: Pay | B7: =COUNTIF('Use cases'!$B$2:$B$119,A7) -> 15 | C7: =COUNTIFS('Use cases'!$B$2:$B$119,$A7,'Use cases'!$P$2:$P$119,1) -> 7 | D7: =COUNTIFS('Use cases'!$B$2:$B$119,$A7,'Use cases'!$P$2:$P$119,2) -> 5 | E7: =COUNTIFS('Use cases'!$B$2:$B$119,$A7,'Use cases'!$P$2:$P$119,3) -> 3 | F7: =IFERROR(ROUND(AVERAGEIF('Use cases'!$B$2:$B$119,A7,'Use cases'!$O$2:$O$119),1),0) -> 4.9
A8: Extras | B8: =COUNTIF('Use cases'!$B$2:$B$119,A8) -> 16 | C8: =COUNTIFS('Use cases'!$B$2:$B$119,$A8,'Use cases'!$P$2:$P$119,1) -> 6 | D8: =COUNTIFS('Use cases'!$B$2:$B$119,$A8,'Use cases'!$P$2:$P$119,2) -> 8 | E8: =COUNTIFS('Use cases'!$B$2:$B$119,$A8,'Use cases'!$P$2:$P$119,3) -> 2 | F8: =IFERROR(ROUND(AVERAGEIF('Use cases'!$B$2:$B$119,A8,'Use cases'!$O$2:$O$119),1),0) -> 7.3
A9: Before the trip | B9: =COUNTIF('Use cases'!$B$2:$B$119,A9) -> 14 | C9: =COUNTIFS('Use cases'!$B$2:$B$119,$A9,'Use cases'!$P$2:$P$119,1) -> 3 | D9: =COUNTIFS('Use cases'!$B$2:$B$119,$A9,'Use cases'!$P$2:$P$119,2) -> 6 | E9: =COUNTIFS('Use cases'!$B$2:$B$119,$A9,'Use cases'!$P$2:$P$119,3) -> 5 | F9: =IFERROR(ROUND(AVERAGEIF('Use cases'!$B$2:$B$119,A9,'Use cases'!$O$2:$O$119),1),0) -> 4.2
A10: Day of travel | B10: =COUNTIF('Use cases'!$B$2:$B$119,A10) -> 10 | C10: =COUNTIFS('Use cases'!$B$2:$B$119,$A10,'Use cases'!$P$2:$P$119,1) -> 4 | D10: =COUNTIFS('Use cases'!$B$2:$B$119,$A10,'Use cases'!$P$2:$P$119,2) -> 3 | E10: =COUNTIFS('Use cases'!$B$2:$B$119,$A10,'Use cases'!$P$2:$P$119,3) -> 3 | F10: =IFERROR(ROUND(AVERAGEIF('Use cases'!$B$2:$B$119,A10,'Use cases'!$O$2:$O$119),1),0) -> 6.1
A11: Disruption | B11: =COUNTIF('Use cases'!$B$2:$B$119,A11) -> 11 | C11: =COUNTIFS('Use cases'!$B$2:$B$119,$A11,'Use cases'!$P$2:$P$119,1) -> 1 | D11: =COUNTIFS('Use cases'!$B$2:$B$119,$A11,'Use cases'!$P$2:$P$119,2) -> 1 | E11: =COUNTIFS('Use cases'!$B$2:$B$119,$A11,'Use cases'!$P$2:$P$119,3) -> 9 | F11: =IFERROR(ROUND(AVERAGEIF('Use cases'!$B$2:$B$119,A11,'Use cases'!$O$2:$O$119),1),0) -> 2
A12: After the trip | B12: =COUNTIF('Use cases'!$B$2:$B$119,A12) -> 6 | C12: =COUNTIFS('Use cases'!$B$2:$B$119,$A12,'Use cases'!$P$2:$P$119,1) -> 4 | D12: =COUNTIFS('Use cases'!$B$2:$B$119,$A12,'Use cases'!$P$2:$P$119,2) -> 1 | E12: =COUNTIFS('Use cases'!$B$2:$B$119,$A12,'Use cases'!$P$2:$P$119,3) -> 1 | F12: =IFERROR(ROUND(AVERAGEIF('Use cases'!$B$2:$B$119,A12,'Use cases'!$O$2:$O$119),1),0) -> 6
A13: Points and card | B13: =COUNTIF('Use cases'!$B$2:$B$119,A13) -> 8 | C13: =COUNTIFS('Use cases'!$B$2:$B$119,$A13,'Use cases'!$P$2:$P$119,1) -> 5 | D13: =COUNTIFS('Use cases'!$B$2:$B$119,$A13,'Use cases'!$P$2:$P$119,2) -> 2 | E13: =COUNTIFS('Use cases'!$B$2:$B$119,$A13,'Use cases'!$P$2:$P$119,3) -> 1 | F13: =IFERROR(ROUND(AVERAGEIF('Use cases'!$B$2:$B$119,A13,'Use cases'!$O$2:$O$119),1),0) -> 8
A14: Total | B14: =SUM(B4:B13) -> 118 | C14: =SUM(C4:C13) -> 52 | D14: =SUM(D4:D13) -> 41 | E14: =SUM(E4:E13) -> 25 | F14: =ROUND(AVERAGE('Use cases'!$O$2:$O$119),1) -> 6.1
A16: Wave 1 is what the agent handles end to end first. Wave 3 needs legal sign-off and a human in the loop before launch.

Sheet Use cases
A1: ID | B1: Stage | C1: Job | D1: Constraint | E1: Exception | F1: Customer says | G1: Gratifi does | H1: UI blocks (kit) | I1: Rules: systems decide | J1: Market notes | K1: Volume | L1: Value | M1: Risk | N1: Core path | O1: Priority | P1: Wave
A2: FL-INS-01 | B2: Inspire | C2: Find somewhere to go | D2: Budget | F2: Somewhere warm in October for under 40,000 points | G2: Suggests 3 places the points cover, with flight price and weather | H2: Answer, Rail, Polaroid, Price | I2: Only places with live fares under the budget | K2: 4 | L2: 3 | M2: 1 | O2: =ROUND(K2*L2/M2,1) -> 12 | P2: =IF(N2="Y",1,IF(M2>='Read me'!$B$14,3,IF(AND(O2>='Read me'!$B$12,M2<='Read me'!$B$13),1,2))) -> 1
A3: FL-INS-02 | B3: Inspire | C3: Find somewhere to go | D3: Dates fixed | F3: Where can I go for the long weekend? | G3: Finds direct flights for those dates, shortest first | H3: Answer, Rail, FlightCard | I3: Uses the bank holiday calendar for the market | J3: Holiday calendars differ per market: bank holidays (UK), Diwali (IN), Eid (AE, MY), Chinese New Year (SG, MY) | K3: 4 | L3: 3 | M3: 1 | O3: =ROUND(K3*L3/M3,1) -> 12 | P3: =IF(N3="Y",1,IF(M3>='Read me'!$B$14,3,IF(AND(O3>='Read me'!$B$12,M3<='Read me'!$B$13),1,2))) -> 1
A4: FL-INS-03 | B4: Inspire | C4: Find somewhere to go | D4: Points only | F4: What can I get with my points alone? | G4: Shows trips fully covered by the balance | H4: Answer, Dial, Rail | I4: Balance and point value from the bank | K4: 4 | L4: 4 | M4: 1 | O4: =ROUND(K4*L4/M4,1) -> 16 | P4: =IF(N4="Y",1,IF(M4>='Read me'!$B$14,3,IF(AND(O4>='Read me'!$B$12,M4<='Read me'!$B$13),1,2))) -> 1
A5: FL-INS-04 | B5: Inspire | C5: Find somewhere to go | D5: Travelling with kids | F5: Somewhere easy with a toddler, short flight | G5: Filters to under 3 hours, direct, family-friendly stays | H5: Answer, Rail, Chips | I5: Flight time cap is a hard filter | K5: 3 | L5: 3 | M5: 1 | O5: =ROUND(K5*L5/M5,1) -> 9 | P5: =IF(N5="Y",1,IF(M5>='Read me'!$B$14,3,IF(AND(O5>='Read me'!$B$12,M5<='Read me'!$B$13),1,2))) -> 1
A6: FL-INS-05 | B6: Inspire | C6: Get a price alert | D6: Route known | F6: Tell me if London to Lisbon drops under £150 | G6: Sets an alert and confirms the threshold | H6: Toast, Toggle | I6: Alert fires on supplier price, not an estimate | K6: 3 | L6: 2 | M6: 1 | O6: =ROUND(K6*L6/M6,1) -> 6 | P6: =IF(N6="Y",1,IF(M6>='Read me'!$B$14,3,IF(AND(O6>='Read me'!$B$12,M6<='Read me'!$B$13),1,2))) -> 1
A7: FL-INS-06 | B7: Inspire | C7: Get told about a deal | D7: Card benefit | F7: (Gratifi starts it) | G7: Moment: a card offer on a route the customer flies often | H7: StickyNote, OfferCard | I7: Only offers the customer is eligible for; marketing consent checked | J7: Consent rules differ: UK GDPR/PECR, EU GDPR, India DPDP Act, Singapore PDPA, Malaysia PDPA, UAE PDPL | K7: 3 | L7: 4 | M7: 2 | O7: =ROUND(K7*L7/M7,1) -> 6 | P7: =IF(N7="Y",1,IF(M7>='Read me'!$B$14,3,IF(AND(O7>='Read me'!$B$12,M7<='Read me'!$B$13),1,2))) -> 1
A8: FL-INS-07 | B8: Inspire | C8: Plan around an event | D8: Date fixed by event | F8: Flights for the F1 weekend | G8: Finds flights and warns about peak prices | H8: Answer, PriceCalendar, StateCard | I8: Event dates from content partner | K8: 2 | L8: 3 | M8: 1 | O8: =ROUND(K8*L8/M8,1) -> 6 | P8: =IF(N8="Y",1,IF(M8>='Read me'!$B$14,3,IF(AND(O8>='Read me'!$B$12,M8<='Read me'!$B$13),1,2))) -> 1
A9: FL-INS-08 | B9: Inspire | C9: Compare two places | D9: Undecided | F9: Lisbon or Porto for 3 nights? | G9: Side-by-side of flight, hotel and total in points | H9: Compare | I9: Totals include taxes | K9: 2 | L9: 3 | M9: 1 | O9: =ROUND(K9*L9/M9,1) -> 6 | P9: =IF(N9="Y",1,IF(M9>='Read me'!$B$14,3,IF(AND(O9>='Read me'!$B$12,M9<='Read me'!$B$13),1,2))) -> 1
A10: FL-SRC-01 | B10: Search | C10: Book a return flight | D10: Dates fixed | F10: Lisbon for two, 16 to 18 October | G10: Three best options with a recommendation and the reason | H10: YouSaid, Steps, Answer, Rail, FlightCard, Suggestions | I10: Supplier fares only; the recommendation reason must be a stated fact | K10: 5 | L10: 5 | M10: 2 | N10: Y | O10: =ROUND(K10*L10/M10,1) -> 12.5 | P10: =IF(N10="Y",1,IF(M10>='Read me'!$B$14,3,IF(AND(O10>='Read me'!$B$12,M10<='Read me'!$B$13),1,2))) -> 1
A11: FL-SRC-02 | B11: Search | C11: Book a return flight | D11: Flexible dates | F11: Cheapest week in October to Lisbon | G11: Price calendar with the cheapest days marked | H11: PriceCalendar | I11: Calendar prices are cached; confirm live before pay | J11: Week starts Sunday in IN and SG, Monday elsewhere | K11: 5 | L11: 4 | M11: 2 | N11: Y | O11: =ROUND(K11*L11/M11,1) -> 10 | P11: =IF(N11="Y",1,IF(M11>='Read me'!$B$14,3,IF(AND(O11>='Read me'!$B$12,M11<='Read me'!$B$13),1,2))) -> 1
A12: FL-SRC-03 | B12: Search | C12: Book a one-way flight | D12: Dates fixed | F12: One way to Dubai on Friday | G12: Results for one-way only | H12: FlightCard, Rail | K12: 4 | L12: 4 | M12: 1 | O12: =ROUND(K12*L12/M12,1) -> 16 | P12: =IF(N12="Y",1,IF(M12>='Read me'!$B$14,3,IF(AND(O12>='Read me'!$B$12,M12<='Read me'!$B$13),1,2))) -> 1
A13: FL-SRC-04 | B13: Search | C13: Book a multi-city trip | D13: Several stops | F13: London to Lisbon, then Porto, then home | G13: Builds the legs and prices them together and separately | H13: Itinerary, Compare | I13: Separate tickets flagged: missed connections not protected | K13: 2 | L13: 4 | M13: 3 | O13: =ROUND(K13*L13/M13,1) -> 2.7 | P13: =IF(N13="Y",1,IF(M13>='Read me'!$B$14,3,IF(AND(O13>='Read me'!$B$12,M13<='Read me'!$B$13),1,2))) -> 2
A14: FL-SRC-05 | B14: Search | C14: Search with filters | D14: Direct only | F14: Only direct | G14: Filters and says how many are left | H14: FilterBar, Chips | K14: 5 | L14: 3 | M14: 1 | O14: =ROUND(K14*L14/M14,1) -> 15 | P14: =IF(N14="Y",1,IF(M14>='Read me'!$B$14,3,IF(AND(O14>='Read me'!$B$12,M14<='Read me'!$B$13),1,2))) -> 1
A15: FL-SRC-06 | B15: Search | C15: Search with filters | D15: Time of day | F15: Nothing before 9am | G15: Filters by departure time | H15: FilterBar | K15: 4 | L15: 3 | M15: 1 | O15: =ROUND(K15*L15/M15,1) -> 12 | P15: =IF(N15="Y",1,IF(M15>='Read me'!$B$14,3,IF(AND(O15>='Read me'!$B$12,M15<='Read me'!$B$13),1,2))) -> 1
A16: FL-SRC-07 | B16: Search | C16: Search with filters | D16: Airline preference | F16: Only airlines where I earn miles | G16: Filters to airlines linked to the customer's schemes | H16: FilterBar, Badge | I16: Frequent flyer numbers from the profile | K16: 3 | L16: 3 | M16: 1 | O16: =ROUND(K16*L16/M16,1) -> 9 | P16: =IF(N16="Y",1,IF(M16>='Read me'!$B$14,3,IF(AND(O16>='Read me'!$B$12,M16<='Read me'!$B$13),1,2))) -> 1
A17: FL-SRC-08 | B17: Search | C17: Search with filters | D17: Bag included | F17: Must include a checked bag | G17: Filters to fares with a checked bag, shows true total | H17: FilterBar, FareFamilies | I17: Total must include the bag | K17: 4 | L17: 3 | M17: 1 | O17: =ROUND(K17*L17/M17,1) -> 12 | P17: =IF(N17="Y",1,IF(M17>='Read me'!$B$14,3,IF(AND(O17>='Read me'!$B$12,M17<='Read me'!$B$13),1,2))) -> 1
A18: FL-SRC-09 | B18: Search | C18: Search nearby airports | D18: City, not airport | F18: Any London airport | G18: Searches all airports for the city | H18: FlightCard | I18: Airport groups per city | K18: 4 | L18: 3 | M18: 1 | O18: =ROUND(K18*L18/M18,1) -> 12 | P18: =IF(N18="Y",1,IF(M18>='Read me'!$B$14,3,IF(AND(O18>='Read me'!$B$12,M18<='Read me'!$B$13),1,2))) -> 1
A19: FL-SRC-10 | B19: Search | C19: Search by voice | D19: Hands busy | F19: (spoken) Flights to Goa next weekend | G19: Transcribes, confirms understanding, searches | H19: AskBar (listening), YouSaid | I19: Shows what it heard before acting | J19: Voice in English first; Hindi, Arabic, Malay later | K19: 3 | L19: 3 | M19: 2 | O19: =ROUND(K19*L19/M19,1) -> 4.5 | P19: =IF(N19="Y",1,IF(M19>='Read me'!$B$14,3,IF(AND(O19>='Read me'!$B$12,M19<='Read me'!$B$13),1,2))) -> 2
A20: FL-SRC-11 | B20: Search | C20: Search for a group | D20: 5 or more | F20: Flights for 8 of us | G20: Checks seat availability for 8, offers group fare route | H20: Travellers, StateCard, Handoff | I20: Over 9 passengers goes to group desk | K20: 2 | L20: 4 | M20: 3 | O20: =ROUND(K20*L20/M20,1) -> 2.7 | P20: =IF(N20="Y",1,IF(M20>='Read me'!$B$14,3,IF(AND(O20>='Read me'!$B$12,M20<='Read me'!$B$13),1,2))) -> 2
A21: FL-SRC-12 | B21: Search | C21: Search premium cabins | D21: Business class | F21: Business class to Singapore | G21: Shows business fares and points cost | H21: FlightCard, FareFamilies | K21: 2 | L21: 5 | M21: 1 | O21: =ROUND(K21*L21/M21,1) -> 10 | P21: =IF(N21="Y",1,IF(M21>='Read me'!$B$14,3,IF(AND(O21>='Read me'!$B$12,M21<='Read me'!$B$13),1,2))) -> 1
A22: FL-SRC-13 | B22: Search | C22: Search with points and cash | D22: Budget in points | F22: Use no more than 20,000 points | G22: Prices each option as points plus cash | H22: PointsSlider, Price | I22: Point value from the bank | K22: 4 | L22: 4 | M22: 1 | O22: =ROUND(K22*L22/M22,1) -> 16 | P22: =IF(N22="Y",1,IF(M22>='Read me'!$B$14,3,IF(AND(O22>='Read me'!$B$12,M22<='Read me'!$B$13),1,2))) -> 1
A23: FL-SRC-14 | B23: Search | C23: Nothing found | D23: Too strict | E23: No results | F23: Direct, before 9am, under £100 | G23: Says which filter blocks it and offers the nearest options | H23: StateCard (empty) | I23: Never invents a flight | K23: 3 | L23: 3 | M23: 1 | O23: =ROUND(K23*L23/M23,1) -> 9 | P23: =IF(N23="Y",1,IF(M23>='Read me'!$B$14,3,IF(AND(O23>='Read me'!$B$12,M23<='Read me'!$B$13),1,2))) -> 1
A24: FL-SRC-15 | B24: Search | C24: Search fails | D24: Supplier down | E24: Timeout | F24: (any search) | G24: Says the airline is not answering, nothing was booked, try again | H24: StateCard (error) | I24: Retry with backoff; switch supplier if available | K24: 2 | L24: 2 | M24: 2 | O24: =ROUND(K24*L24/M24,1) -> 2 | P24: =IF(N24="Y",1,IF(M24>='Read me'!$B$14,3,IF(AND(O24>='Read me'!$B$12,M24<='Read me'!$B$13),1,2))) -> 2
A25: FL-SRC-16 | B25: Search | C25: Book a return flight | D25: Open jaw | F25: Fly into Lisbon, back from Porto | G25: Prices the open jaw as one trip | H25: Itinerary, FlightCard | I25: Fare construction by supplier | K25: 2 | L25: 3 | M25: 2 | O25: =ROUND(K25*L25/M25,1) -> 3 | P25: =IF(N25="Y",1,IF(M25>='Read me'!$B$14,3,IF(AND(O25>='Read me'!$B$12,M25<='Read me'!$B$13),1,2))) -> 2
A26: FL-SRC-17 | B26: Search | C26: Book for someone else | D26: Gift trip | F26: Book flights for my parents | G26: Captures their names, pays from my points | H26: Travellers, PayWith | I26: Names must match passports | K26: 2 | L26: 4 | M26: 3 | O26: =ROUND(K26*L26/M26,1) -> 2.7 | P26: =IF(N26="Y",1,IF(M26>='Read me'!$B$14,3,IF(AND(O26>='Read me'!$B$12,M26<='Read me'!$B$13),1,2))) -> 2
A27: FL-SRC-18 | B27: Search | C27: Book last minute | D27: Today | F27: Next flight to Edinburgh | G27: Shows flights leaving soonest with check-in cut-off | H27: FlightCard, Status | I27: Cut-off times per airline | K27: 2 | L27: 4 | M27: 2 | O27: =ROUND(K27*L27/M27,1) -> 4 | P27: =IF(N27="Y",1,IF(M27>='Read me'!$B$14,3,IF(AND(O27>='Read me'!$B$12,M27<='Read me'!$B$13),1,2))) -> 2
A28: FL-CHO-01 | B28: Choose | C28: Choose between flights | D28: Two close options | F28: Which is better, the 7am or the 11am? | G28: Compares on what differs: time, bag, price, points back | H28: Compare | I28: Only facts from the fares | K28: 4 | L28: 4 | M28: 1 | O28: =ROUND(K28*L28/M28,1) -> 16 | P28: =IF(N28="Y",1,IF(M28>='Read me'!$B$14,3,IF(AND(O28>='Read me'!$B$12,M28<='Read me'!$B$13),1,2))) -> 1
A29: FL-CHO-02 | B29: Choose | C29: Understand a fare | D29: Unsure what is included | F29: Does Light include a bag? | G29: Shows fare families, ticked and greyed | H29: FareFamilies | I29: Fare rules from the supplier, word for word in the source | K29: 5 | L29: 4 | M29: 2 | N29: Y | O29: =ROUND(K29*L29/M29,1) -> 10 | P29: =IF(N29="Y",1,IF(M29>='Read me'!$B$14,3,IF(AND(O29>='Read me'!$B$12,M29<='Read me'!$B$13),1,2))) -> 1
A30: FL-CHO-03 | B30: Choose | C30: Understand change rules | D30: Might change plans | F30: Can I change the date later? | G30: Plain-words fare rules: free, fee, not possible | H30: FareRules | I30: Rules from fare; never guessed | K30: 4 | L30: 4 | M30: 3 | O30: =ROUND(K30*L30/M30,1) -> 5.3 | P30: =IF(N30="Y",1,IF(M30>='Read me'!$B$14,3,IF(AND(O30>='Read me'!$B$12,M30<='Read me'!$B$13),1,2))) -> 2
A31: FL-CHO-04 | B31: Choose | C31: See the full journey | D31: Connection | F31: How long is the stop in Porto? | G31: Itinerary with layover; tight ones in amber | H31: Itinerary | I31: Minimum connection time per airport | K31: 3 | L31: 3 | M31: 2 | O31: =ROUND(K31*L31/M31,1) -> 4.5 | P31: =IF(N31="Y",1,IF(M31>='Read me'!$B$14,3,IF(AND(O31>='Read me'!$B$12,M31<='Read me'!$B$13),1,2))) -> 2
A32: FL-CHO-05 | B32: Choose | C32: See the plane | D32: Comfort | F32: What plane is it? | G32: Aircraft type and seat pitch if known | H32: Itinerary, Meta | K32: 2 | L32: 2 | M32: 1 | O32: =ROUND(K32*L32/M32,1) -> 4 | P32: =IF(N32="Y",1,IF(M32>='Read me'!$B$14,3,IF(AND(O32>='Read me'!$B$12,M32<='Read me'!$B$13),1,2))) -> 2
A33: FL-CHO-06 | B33: Choose | C33: Choose travellers | D33: Children | F33: Two adults and a 3 year old | G33: Sets travellers with correct age bands | H33: Travellers | I33: Age on the day of travel; airline bands | K33: 4 | L33: 3 | M33: 2 | O33: =ROUND(K33*L33/M33,1) -> 6 | P33: =IF(N33="Y",1,IF(M33>='Read me'!$B$14,3,IF(AND(O33>='Read me'!$B$12,M33<='Read me'!$B$13),1,2))) -> 1
A34: FL-CHO-07 | B34: Choose | C34: Choose travellers | D34: Infant on lap | F34: Plus a baby | G34: Adds infant, one per adult | H34: Travellers | I34: Infants never exceed adults | K34: 3 | L34: 3 | M34: 2 | O34: =ROUND(K34*L34/M34,1) -> 4.5 | P34: =IF(N34="Y",1,IF(M34>='Read me'!$B$14,3,IF(AND(O34>='Read me'!$B$12,M34<='Read me'!$B$13),1,2))) -> 2
A35: FL-CHO-08 | B35: Choose | C35: Choose travellers | D35: Travelling alone as a minor | F35: My daughter is flying alone, she's 13 | G35: Explains the airline's unaccompanied minor service and hands over | H35: StateCard, Handoff | I35: Unaccompanied minors always go to a person | K35: 1 | L35: 3 | M35: 5 | O35: =ROUND(K35*L35/M35,1) -> 0.6 | P35: =IF(N35="Y",1,IF(M35>='Read me'!$B$14,3,IF(AND(O35>='Read me'!$B$12,M35<='Read me'!$B$13),1,2))) -> 3
A36: FL-CHO-09 | B36: Choose | C36: Price changed | D36: Between search and choose | E36: Fare rose | F36: (taps a flight) | G36: Shows old and new price, asks to continue | H36: StateCard (price) | I36: Never book at a higher price without a new yes | K36: 3 | L36: 3 | M36: 3 | O36: =ROUND(K36*L36/M36,1) -> 3 | P36: =IF(N36="Y",1,IF(M36>='Read me'!$B$14,3,IF(AND(O36>='Read me'!$B$12,M36<='Read me'!$B$13),1,2))) -> 2
A37: FL-CHO-10 | B37: Choose | C37: Sold out | D37: Last seats | E37: Fare gone | F37: (taps a flight) | G37: Says it has gone and offers the next best | H37: StateCard (soldout) | K37: 3 | L37: 3 | M37: 2 | O37: =ROUND(K37*L37/M37,1) -> 4.5 | P37: =IF(N37="Y",1,IF(M37>='Read me'!$B$14,3,IF(AND(O37>='Read me'!$B$12,M37<='Read me'!$B$13),1,2))) -> 2
A38: FL-CHO-11 | B38: Choose | C38: Hold a fare | D38: Deciding | F38: Can you hold this for a day? | G38: Offers fare hold if the airline sells it | H38: StateCard, ConfirmSheet | I38: Hold price and time from the airline | K38: 2 | L38: 3 | M38: 3 | O38: =ROUND(K38*L38/M38,1) -> 2 | P38: =IF(N38="Y",1,IF(M38>='Read me'!$B$14,3,IF(AND(O38>='Read me'!$B$12,M38<='Read me'!$B$13),1,2))) -> 2
A39: FL-CHO-12 | B39: Choose | C39: Check the carbon | D39: Green choice | F39: Which one is lower carbon? | G39: Shows estimated emissions per option | H39: Compare | I39: Estimate from a named source | J39: Carbon disclosure rules vary; EU strictest | K39: 1 | L39: 2 | M39: 2 | O39: =ROUND(K39*L39/M39,1) -> 1 | P39: =IF(N39="Y",1,IF(M39>='Read me'!$B$14,3,IF(AND(O39>='Read me'!$B$12,M39<='Read me'!$B$13),1,2))) -> 2
A40: FL-PAY-01 | B40: Pay | C40: Pay with points | D40: Enough points | F40: Pay with points | G40: Shows points total, confirm, done | H40: PayWith, ConfirmSheet, Receipt | I40: Points value from the bank; spend needs a button with the amount | J40: Confirm: Face ID (UK, EU, AE, SG), one-time code (IN), bank app approval (MY) | K40: 5 | L40: 5 | M40: 3 | N40: Y | O40: =ROUND(K40*L40/M40,1) -> 8.3 | P40: =IF(N40="Y",1,IF(M40>='Read me'!$B$14,3,IF(AND(O40>='Read me'!$B$12,M40<='Read me'!$B$13),1,2))) -> 1
...

Sheet Markets
A1: Market | B1: Currency | C1: Number and date format | D1: How a payment is confirmed | E1: Automatic card payment is called | F1: Tax on fares | G1: Flight disruption rule | H1: Amounts set in law? | I1: Week starts | J1: Languages | K1: To confirm with the bank
A2: United Kingdom | B2: GBP £ | C2: en-GB · 1,234.50 · Fri 16 Oct | D2: Face ID in the bank app | E2: Direct Debit | F2: VAT; Air Passenger Duty in fares | G2: UK261 | H2: Yes: £220, £350, £520 by distance | I2: Monday | J2: English | K2: Point value; claims process
A3: Eurozone | B3: EUR € | C3: en-IE for English; local languages later | D3: Face ID in the bank app (strong customer authentication) | E3: direct debit | F3: VAT; local ticket taxes | G3: EU261 | H3: Yes: €250, €400, €600 by distance | I3: Monday | J3: English first; German, French, Spanish, Italian, Dutch to add | K3: Point value; which languages first
A4: India | B4: INR ₹ | C4: en-IN · lakh grouping (1,00,000) · Fri 16 Oct | D4: One-time code sent by SMS | E4: auto-debit | F4: GST; GST invoice needs company GSTIN | G4: DGCA passenger charter | H4: Set by DGCA; legal team to confirm current amounts | I4: Sunday | J4: English first; Hindi next | K4: Point value; OTP limits; EMI terms
A5: UAE | B5: AED | C5: en-AE and ar-AE (right to left) | D5: Face ID in the bank app | E5: direct debit | F5: VAT | G5: Airline policy (legal team to confirm any GCAA rule) | H5: Legal team to confirm | I5: Monday | J5: English and Arabic (Arabic copy needs native sign-off) | K5: Point value; Arabic copy
A6: Singapore | B6: SGD S$ | C6: en-SG · 1,234.50 | D6: Face ID in the bank app | E6: GIRO | F6: GST | G6: Airline policy; no statutory scheme | H6: No | I6: Sunday | J6: English | K6: Point value
A7: Malaysia | B7: MYR RM | C7: en-MY · 1,234.50 | D7: Approval in the bank's app | E7: auto-debit | F7: SST | G7: MAVCOM consumer code | H7: Legal team to confirm | I7: Monday | J7: English first; Malay next | K7: Point value; app approval flow
A9: These settings live in the kit as data (Markets card). A new market is one more row here and one more entry in the kit; no redesign.

Sheet Grammar
A1: The grammar
A3: Stage | B3: Means | C3: Constraints | D3: Exceptions
A4: Inspire | B4: Before they know where | C4: Dates fixed | D4: No results
A5: Search | B5: They know roughly what and when | C5: Flexible dates | D5: Supplier down
A6: Choose | B6: Comparing options and fares | C6: Budget in cash | D6: Price rose
A7: Pay | B7: Money or points move | C7: Budget in points | D7: Sold out
A8: Extras | B8: Seats, bags, lounge, hotel, rides | C8: Direct only | D8: Payment declined
A9: Before the trip | B9: Booked, not yet travelling | C9: Time of day | D9: Authentication failed
A10: Day of travel | B10: At or on the way to the airport | C10: Airline preference | D10: Not enough points
A11: Disruption | B11: Something went wrong | C11: Bag included | D11: Ticketing pending
A12: After the trip | B12: Home again | C12: Travelling with children | D12: Schedule change
A13: Points and card | B13: The bank side of travel | C13: Group of 5 or more | D13: Delay over 3 hours
C14: Premium cabin | D14: Cancellation
C15: Business trip | D15: Missed connection
C16: Accessibility needs | D16: Denied boarding
C17: Pet | D17: Diversion
C18: Separate tickets | D18: Downgrade
D19: Lost bag
A22: Every new row should combine one stage, one job, at most one constraint and at most one exception. The full space is several hundred rows; this sheet holds the ones worth building first plus the high-risk ones that must be designed now.
