Workbook

Sheet Read me
A1: Gratifi: every use case
A2: Everything a bank's customer can ask Gratifi to do, across every product, service and piece of content R360 and Gratifi provide. One row is one thing a customer wants done in one situation: what they say, what Gratifi does, which UI kit blocks it uses, what the systems decide, and what changes by market.
A4: What is covered
A5: 19 categories and 105 products and services (sheet "Coverage"), built from: the Commerce in chat doc (18 categories and the R360 project list: Open Rewards, TripSure, PHANTOM, Airport VIP, iRewards 2.0, Piingle, new-age rewards, ZERO, Gratifi, R360 core), CACHE, and the Gratifi app sitemap (12 bank areas and every sub-area).
A6: Nothing counts as covered until "Coverage" shows zero gaps. An item is covered when it has at least 6 use cases, at least 2 where nothing goes wrong and at least 2 where something does. Add a product to "Coverage" and it shows as a gap until its use cases exist.
A8: How a row is built
A9: Stage × Job × Constraint × Exception. Stages: Discover, Search, Choose, Pay, Add-ons, Before, During, Problem, After, Account. "Customer says" is one example phrasing; the agent is trained on many per row. "Rules" are decided by systems, never by the model.
A10: "UI blocks" names components in the Gratifi UI kit. "NEW: Name" means the kit does not have that block yet; sheet "Kit gaps" lists every one and how often it is needed.
A12: Scoring (1 low to 5 high) and build waves
A13: Volume: how often customers ask. Value: revenue or loyalty impact. Risk: harm if wrong (money, rights, safety, regulation). Priority = Volume × Value ÷ Risk. Edit the blue cells to change the waves.
A14: Wave 1 needs priority of at least | B14: 6
A15: Wave 1 needs risk no higher than | B15: 2
A16: Risk of at least this goes to wave 3 (legal and human sign-off first) | B16: 4
A17: Core path (Y) rows are wave 1 even at high risk, because a customer cannot complete a booking without them; legal still signs off the high-risk ones before launch.
A19: Status and cautions
A20: • Scores are a first pass for discussion. Re-score with real volumes from partner banks and PHANTOM and TripSure history.
A21: • Compensation and consumer-law amounts are given only where set by law and known (UK261, EU261, UK Section 75). Anything else is named and marked "to confirm" for each bank's legal team. Market notes are prompts to check, not legal advice.
A22: • Investments (C13) and insurance selling need licences per market; those rows are information-only until legal signs off.
A23: • Arabic copy in the kit is a layout draft for native review. Suppliers, airlines and hotels in examples are fictional unless the inventory names the supply.
A24: • To add a use case: add a row at the bottom of "Use cases", fill the item ID and scores; copy Priority and Wave down.

Sheet Summary
A1: Summary
A3: Items with a coverage gap | B3: =COUNTIF(Coverage!$N$2:$N$156,"GAP") -> 0
A4: Use cases | B4: =COUNTA('Use cases'!$C$2:$C$6000) -> 2315
A5: Products and services | B5: =COUNTIF(Coverage!$N$2:$N$156,"Covered")+COUNTIF(Coverage!$N$2:$N$156,"GAP") -> 105
A6: Kit blocks still to build | B6: =COUNTA('Kit gaps'!$A$2:$A$500) -> 106
A8: Category | B8: Products | C8: Use cases | D8: Wave 1 | E8: Wave 2 | F8: Wave 3 | G8: Gaps | H8: Average priority
A9: Flights | B9: =COUNTIF(Coverage!$B$2:$B$156,A9) -> 8 | C9: =COUNTIF('Use cases'!$B$2:$B$6000,A9) -> 146 | D9: =COUNTIFS('Use cases'!$B$2:$B$6000,$A9,'Use cases'!$S$2:$S$6000,1) -> 61 | E9: =COUNTIFS('Use cases'!$B$2:$B$6000,$A9,'Use cases'!$S$2:$S$6000,2) -> 56 | F9: =COUNTIFS('Use cases'!$B$2:$B$6000,$A9,'Use cases'!$S$2:$S$6000,3) -> 29 | G9: =COUNTIFS(Coverage!$B$2:$B$156,A9,Coverage!$N$2:$N$156,"GAP") -> 0 | H9: =IFERROR(ROUND(AVERAGEIF('Use cases'!$B$2:$B$6000,A9,'Use cases'!$R$2:$R$6000),1),0) -> 5.4
A10: Stays | B10: =COUNTIF(Coverage!$B$2:$B$156,A10) -> 6 | C10: =COUNTIF('Use cases'!$B$2:$B$6000,A10) -> 119 | D10: =COUNTIFS('Use cases'!$B$2:$B$6000,$A10,'Use cases'!$S$2:$S$6000,1) -> 31 | E10: =COUNTIFS('Use cases'!$B$2:$B$6000,$A10,'Use cases'!$S$2:$S$6000,2) -> 57 | F10: =COUNTIFS('Use cases'!$B$2:$B$6000,$A10,'Use cases'!$S$2:$S$6000,3) -> 31 | G10: =COUNTIFS(Coverage!$B$2:$B$156,A10,Coverage!$N$2:$N$156,"GAP") -> 0 | H10: =IFERROR(ROUND(AVERAGEIF('Use cases'!$B$2:$B$6000,A10,'Use cases'!$R$2:$R$6000),1),0) -> 4.4
A11: Airport and travel privileges | B11: =COUNTIF(Coverage!$B$2:$B$156,A11) -> 6 | C11: =COUNTIF('Use cases'!$B$2:$B$6000,A11) -> 110 | D11: =COUNTIFS('Use cases'!$B$2:$B$6000,$A11,'Use cases'!$S$2:$S$6000,1) -> 22 | E11: =COUNTIFS('Use cases'!$B$2:$B$6000,$A11,'Use cases'!$S$2:$S$6000,2) -> 71 | F11: =COUNTIFS('Use cases'!$B$2:$B$6000,$A11,'Use cases'!$S$2:$S$6000,3) -> 17 | G11: =COUNTIFS(Coverage!$B$2:$B$156,A11,Coverage!$N$2:$N$156,"GAP") -> 0 | H11: =IFERROR(ROUND(AVERAGEIF('Use cases'!$B$2:$B$6000,A11,'Use cases'!$R$2:$R$6000),1),0) -> 3.6
A12: Ground transport | B12: =COUNTIF(Coverage!$B$2:$B$156,A12) -> 5 | C12: =COUNTIF('Use cases'!$B$2:$B$6000,A12) -> 94 | D12: =COUNTIFS('Use cases'!$B$2:$B$6000,$A12,'Use cases'!$S$2:$S$6000,1) -> 17 | E12: =COUNTIFS('Use cases'!$B$2:$B$6000,$A12,'Use cases'!$S$2:$S$6000,2) -> 64 | F12: =COUNTIFS('Use cases'!$B$2:$B$6000,$A12,'Use cases'!$S$2:$S$6000,3) -> 13 | G12: =COUNTIFS(Coverage!$B$2:$B$156,A12,Coverage!$N$2:$N$156,"GAP") -> 0 | H12: =IFERROR(ROUND(AVERAGEIF('Use cases'!$B$2:$B$6000,A12,'Use cases'!$R$2:$R$6000),1),0) -> 3.4
A13: Experiences | B13: =COUNTIF(Coverage!$B$2:$B$156,A13) -> 5 | C13: =COUNTIF('Use cases'!$B$2:$B$6000,A13) -> 153 | D13: =COUNTIFS('Use cases'!$B$2:$B$6000,$A13,'Use cases'!$S$2:$S$6000,1) -> 39 | E13: =COUNTIFS('Use cases'!$B$2:$B$6000,$A13,'Use cases'!$S$2:$S$6000,2) -> 83 | F13: =COUNTIFS('Use cases'!$B$2:$B$6000,$A13,'Use cases'!$S$2:$S$6000,3) -> 31 | G13: =COUNTIFS(Coverage!$B$2:$B$156,A13,Coverage!$N$2:$N$156,"GAP") -> 0 | H13: =IFERROR(ROUND(AVERAGEIF('Use cases'!$B$2:$B$6000,A13,'Use cases'!$R$2:$R$6000),1),0) -> 4.2
A14: Dining | B14: =COUNTIF(Coverage!$B$2:$B$156,A14) -> 4 | C14: =COUNTIF('Use cases'!$B$2:$B$6000,A14) -> 102 | D14: =COUNTIFS('Use cases'!$B$2:$B$6000,$A14,'Use cases'!$S$2:$S$6000,1) -> 37 | E14: =COUNTIFS('Use cases'!$B$2:$B$6000,$A14,'Use cases'!$S$2:$S$6000,2) -> 61 | F14: =COUNTIFS('Use cases'!$B$2:$B$6000,$A14,'Use cases'!$S$2:$S$6000,3) -> 4 | G14: =COUNTIFS(Coverage!$B$2:$B$156,A14,Coverage!$N$2:$N$156,"GAP") -> 0 | H14: =IFERROR(ROUND(AVERAGEIF('Use cases'!$B$2:$B$6000,A14,'Use cases'!$R$2:$R$6000),1),0) -> 5
A15: Quick commerce and grocery | B15: =COUNTIF(Coverage!$B$2:$B$156,A15) -> 3 | C15: =COUNTIF('Use cases'!$B$2:$B$6000,A15) -> 103 | D15: =COUNTIFS('Use cases'!$B$2:$B$6000,$A15,'Use cases'!$S$2:$S$6000,1) -> 27 | E15: =COUNTIFS('Use cases'!$B$2:$B$6000,$A15,'Use cases'!$S$2:$S$6000,2) -> 62 | F15: =COUNTIFS('Use cases'!$B$2:$B$6000,$A15,'Use cases'!$S$2:$S$6000,3) -> 14 | G15: =COUNTIFS(Coverage!$B$2:$B$156,A15,Coverage!$N$2:$N$156,"GAP") -> 0 | H15: =IFERROR(ROUND(AVERAGEIF('Use cases'!$B$2:$B$6000,A15,'Use cases'!$R$2:$R$6000),1),0) -> 4.6
A16: Shopping | B16: =COUNTIF(Coverage!$B$2:$B$156,A16) -> 7 | C16: =COUNTIF('Use cases'!$B$2:$B$6000,A16) -> 204 | D16: =COUNTIFS('Use cases'!$B$2:$B$6000,$A16,'Use cases'!$S$2:$S$6000,1) -> 65 | E16: =COUNTIFS('Use cases'!$B$2:$B$6000,$A16,'Use cases'!$S$2:$S$6000,2) -> 109 | F16: =COUNTIFS('Use cases'!$B$2:$B$6000,$A16,'Use cases'!$S$2:$S$6000,3) -> 30 | G16: =COUNTIFS(Coverage!$B$2:$B$156,A16,Coverage!$N$2:$N$156,"GAP") -> 0 | H16: =IFERROR(ROUND(AVERAGEIF('Use cases'!$B$2:$B$6000,A16,'Use cases'!$R$2:$R$6000),1),0) -> 4.9
A17: Gift cards | B17: =COUNTIF(Coverage!$B$2:$B$156,A17) -> 5 | C17: =COUNTIF('Use cases'!$B$2:$B$6000,A17) -> 88 | D17: =COUNTIFS('Use cases'!$B$2:$B$6000,$A17,'Use cases'!$S$2:$S$6000,1) -> 21 | E17: =COUNTIFS('Use cases'!$B$2:$B$6000,$A17,'Use cases'!$S$2:$S$6000,2) -> 47 | F17: =COUNTIFS('Use cases'!$B$2:$B$6000,$A17,'Use cases'!$S$2:$S$6000,3) -> 20 | G17: =COUNTIFS(Coverage!$B$2:$B$156,A17,Coverage!$N$2:$N$156,"GAP") -> 0 | H17: =IFERROR(ROUND(AVERAGEIF('Use cases'!$B$2:$B$6000,A17,'Use cases'!$R$2:$R$6000),1),0) -> 3.7
A18: Subscriptions and digital | B18: =COUNTIF(Coverage!$B$2:$B$156,A18) -> 6 | C18: =COUNTIF('Use cases'!$B$2:$B$6000,A18) -> 88 | D18: =COUNTIFS('Use cases'!$B$2:$B$6000,$A18,'Use cases'!$S$2:$S$6000,1) -> 18 | E18: =COUNTIFS('Use cases'!$B$2:$B$6000,$A18,'Use cases'!$S$2:$S$6000,2) -> 65 | F18: =COUNTIFS('Use cases'!$B$2:$B$6000,$A18,'Use cases'!$S$2:$S$6000,3) -> 5 | G18: =COUNTIFS(Coverage!$B$2:$B$156,A18,Coverage!$N$2:$N$156,"GAP") -> 0 | H18: =IFERROR(ROUND(AVERAGEIF('Use cases'!$B$2:$B$6000,A18,'Use cases'!$R$2:$R$6000),1),0) -> 3.6
A19: Entertainment tickets | B19: =COUNTIF(Coverage!$B$2:$B$156,A19) -> 5 | C19: =COUNTIF('Use cases'!$B$2:$B$6000,A19) -> 115 | D19: =COUNTIFS('Use cases'!$B$2:$B$6000,$A19,'Use cases'!$S$2:$S$6000,1) -> 34 | E19: =COUNTIFS('Use cases'!$B$2:$B$6000,$A19,'Use cases'!$S$2:$S$6000,2) -> 74 | F19: =COUNTIFS('Use cases'!$B$2:$B$6000,$A19,'Use cases'!$S$2:$S$6000,3) -> 7 | G19: =COUNTIFS(Coverage!$B$2:$B$156,A19,Coverage!$N$2:$N$156,"GAP") -> 0 | H19: =IFERROR(ROUND(AVERAGEIF('Use cases'!$B$2:$B$6000,A19,'Use cases'!$R$2:$R$6000),1),0) -> 4.6
A20: Points and miles | B20: =COUNTIF(Coverage!$B$2:$B$156,A20) -> 7 | C20: =COUNTIF('Use cases'!$B$2:$B$6000,A20) -> 106 | D20: =COUNTIFS('Use cases'!$B$2:$B$6000,$A20,'Use cases'!$S$2:$S$6000,1) -> 29 | E20: =COUNTIFS('Use cases'!$B$2:$B$6000,$A20,'Use cases'!$S$2:$S$6000,2) -> 57 | F20: =COUNTIFS('Use cases'!$B$2:$B$6000,$A20,'Use cases'!$S$2:$S$6000,3) -> 20 | G20: =COUNTIFS(Coverage!$B$2:$B$156,A20,Coverage!$N$2:$N$156,"GAP") -> 0 | H20: =IFERROR(ROUND(AVERAGEIF('Use cases'!$B$2:$B$6000,A20,'Use cases'!$R$2:$R$6000),1),0) -> 4.1
... A27: Engagement and moments | B27: =COUNTIF(Coverage!$B$2:$B$156,A27) -> 6 | C27: =COUNTIF('Use cases'!$B$2:$B$6000,A27) -> 131 | D27: =COUNTIFS('Use cases'!$B$2:$B$6000,$A27,'Use cases'!$S$2:$S$6000,1) -> 30 | E27: =COUNTIFS('Use cases'!$B$2:$B$6000,$A27,'Use cases'!$S$2:$S$6000,2) -> 84 | F27: =COUNTIFS('Use cases'!$B$2:$B$6000,$A27,'Use cases'!$S$2:$S$6000,3) -> 17 | G27: =COUNTIFS(Coverage!$B$2:$B$156,A27,Coverage!$N$2:$N$156,"GAP") -> 0 | H27: =IFERROR(ROUND(AVERAGEIF('Use cases'!$B$2:$B$6000,A27,'Use cases'!$R$2:$R$6000),1),0) -> 3.4
A28: Total | B28: =SUM(B9:B27) -> 105 | C28: =SUM(C9:C27) -> 2315 | D28: =SUM(D9:D27) -> 512 | E28: =SUM(E9:E27) -> 1285 | F28: =SUM(F9:F27) -> 518 | G28: =SUM(G9:G27) -> 0 | H28: =ROUND(AVERAGE('Use cases'!$R$2:$R$6000),1) -> 3.8
A30: Wave 1 is what the agent handles end to end first. Wave 3 needs legal sign-off and a person in the loop before launch.

Sheet Coverage
A1: Item ID | B1: Category | C1: Item | D1: What it covers | E1: Supply | F1: Status as last recorded | G1: Use cases | H1: Nothing wrong | I1: Something wrong | J1: Pay rows | K1: Handovers | L1: Proactive | M1: New blocks needed | N1: Coverage
A2: FL-01 | B2: Flights | C2: One-way and return flights | D2: Search, compare, book | E2: TripSure, PHANTOM (TBO, TripJack, MistyFly), Kiwi.com and Expedia MCPs | F2: In build | G2: =COUNTIF('Use cases'!$C$2:$C$6000,A2) -> 34 | H2: =COUNTIFS('Use cases'!$C$2:$C$6000,A2,'Use cases'!$H$2:$H$6000,"") -> 30 | I2: =G2-H2 -> 4 | J2: =COUNTIFS('Use cases'!$C$2:$C$6000,A2,'Use cases'!$E$2:$E$6000,"Pay") -> 0 | K2: =COUNTIFS('Use cases'!$C$2:$C$6000,A2,'Use cases'!$K$2:$K$6000,"*Handoff*") -> 1 | L2: =COUNTIFS('Use cases'!$C$2:$C$6000,A2,'Use cases'!$I$2:$I$6000,"(Gratifi starts it)*") -> 1 | M2: =COUNTIFS('Use cases'!$C$2:$C$6000,A2,'Use cases'!$K$2:$K$6000,"*NEW:*") -> 0 | N2: =IF(AND(G2>=6,H2>=2,I2>=2),"Covered","GAP") -> Covered
A3: FL-02 | B3: Flights | C3: Multi-city, open jaw, groups | D3: Complex itineraries | E3: Same as FL-01 | F3: In build | G3: =COUNTIF('Use cases'!$C$2:$C$6000,A3) -> 10 | H3: =COUNTIFS('Use cases'!$C$2:$C$6000,A3,'Use cases'!$H$2:$H$6000,"") -> 7 | I3: =G3-H3 -> 3 | J3: =COUNTIFS('Use cases'!$C$2:$C$6000,A3,'Use cases'!$E$2:$E$6000,"Pay") -> 2 | K3: =COUNTIFS('Use cases'!$C$2:$C$6000,A3,'Use cases'!$K$2:$K$6000,"*Handoff*") -> 3 | L3: =COUNTIFS('Use cases'!$C$2:$C$6000,A3,'Use cases'!$I$2:$I$6000,"(Gratifi starts it)*") -> 0 | M3: =COUNTIFS('Use cases'!$C$2:$C$6000,A3,'Use cases'!$K$2:$K$6000,"*NEW:*") -> 0 | N3: =IF(AND(G3>=6,H3>=2,I3>=2),"Covered","GAP") -> Covered
A4: FL-03 | B4: Flights | C4: Award seats and upgrades | D4: Points for seats and cabins | E4: Bank programmes, airline partners | F4: To source | G4: =COUNTIF('Use cases'!$C$2:$C$6000,A4) -> 9 | H4: =COUNTIFS('Use cases'!$C$2:$C$6000,A4,'Use cases'!$H$2:$H$6000,"") -> 7 | I4: =G4-H4 -> 2 | J4: =COUNTIFS('Use cases'!$C$2:$C$6000,A4,'Use cases'!$E$2:$E$6000,"Pay") -> 1 | K4: =COUNTIFS('Use cases'!$C$2:$C$6000,A4,'Use cases'!$K$2:$K$6000,"*Handoff*") -> 1 | L4: =COUNTIFS('Use cases'!$C$2:$C$6000,A4,'Use cases'!$I$2:$I$6000,"(Gratifi starts it)*") -> 1 | M4: =COUNTIFS('Use cases'!$C$2:$C$6000,A4,'Use cases'!$K$2:$K$6000,"*NEW:*") -> 0 | N4: =IF(AND(G4>=6,H4>=2,I4>=2),"Covered","GAP") -> Covered
A5: FL-04 | B5: Flights | C5: Seats, bags, meals, assistance | D5: Ancillaries | E5: Supplier APIs | F5: In build | G5: =COUNTIF('Use cases'!$C$2:$C$6000,A5) -> 18 | H5: =COUNTIFS('Use cases'!$C$2:$C$6000,A5,'Use cases'!$H$2:$H$6000,"") -> 14 | I5: =G5-H5 -> 4 | J5: =COUNTIFS('Use cases'!$C$2:$C$6000,A5,'Use cases'!$E$2:$E$6000,"Pay") -> 0 | K5: =COUNTIFS('Use cases'!$C$2:$C$6000,A5,'Use cases'!$K$2:$K$6000,"*Handoff*") -> 3 | L5: =COUNTIFS('Use cases'!$C$2:$C$6000,A5,'Use cases'!$I$2:$I$6000,"(Gratifi starts it)*") -> 0 | M5: =COUNTIFS('Use cases'!$C$2:$C$6000,A5,'Use cases'!$K$2:$K$6000,"*NEW:*") -> 0 | N5: =IF(AND(G5>=6,H5>=2,I5>=2),"Covered","GAP") -> Covered
A6: FL-05 | B6: Flights | C6: Changes and cancellations | D6: Manage booking | E6: Supplier APIs, fare rules | F6: In build | G6: =COUNTIF('Use cases'!$C$2:$C$6000,A6) -> 11 | H6: =COUNTIFS('Use cases'!$C$2:$C$6000,A6,'Use cases'!$H$2:$H$6000,"") -> 8 | I6: =G6-H6 -> 3 | J6: =COUNTIFS('Use cases'!$C$2:$C$6000,A6,'Use cases'!$E$2:$E$6000,"Pay") -> 0 | K6: =COUNTIFS('Use cases'!$C$2:$C$6000,A6,'Use cases'!$K$2:$K$6000,"*Handoff*") -> 1 | L6: =COUNTIFS('Use cases'!$C$2:$C$6000,A6,'Use cases'!$I$2:$I$6000,"(Gratifi starts it)*") -> 0 | M6: =COUNTIFS('Use cases'!$C$2:$C$6000,A6,'Use cases'!$K$2:$K$6000,"*NEW:*") -> 0 | N6: =IF(AND(G6>=6,H6>=2,I6>=2),"Covered","GAP") -> Covered
A7: FL-06 | B7: Flights | C7: Check-in and day of travel | D7: Boarding pass, status, gate | E7: Airline feeds | F7: In build | G7: =COUNTIF('Use cases'!$C$2:$C$6000,A7) -> 23 | H7: =COUNTIFS('Use cases'!$C$2:$C$6000,A7,'Use cases'!$H$2:$H$6000,"") -> 19 | I7: =G7-H7 -> 4 | J7: =COUNTIFS('Use cases'!$C$2:$C$6000,A7,'Use cases'!$E$2:$E$6000,"Pay") -> 0 | K7: =COUNTIFS('Use cases'!$C$2:$C$6000,A7,'Use cases'!$K$2:$K$6000,"*Handoff*") -> 3 | L7: =COUNTIFS('Use cases'!$C$2:$C$6000,A7,'Use cases'!$I$2:$I$6000,"(Gratifi starts it)*") -> 2 | M7: =COUNTIFS('Use cases'!$C$2:$C$6000,A7,'Use cases'!$K$2:$K$6000,"*NEW:*") -> 0 | N7: =IF(AND(G7>=6,H7>=2,I7>=2),"Covered","GAP") -> Covered
A8: FL-07 | B8: Flights | C8: Disruption and compensation | D8: Delays, cancellations, claims | E8: Airline feeds, local rules | F8: In build | G8: =COUNTIF('Use cases'!$C$2:$C$6000,A8) -> 15 | H8: =COUNTIFS('Use cases'!$C$2:$C$6000,A8,'Use cases'!$H$2:$H$6000,"") -> 4 | I8: =G8-H8 -> 11 | J8: =COUNTIFS('Use cases'!$C$2:$C$6000,A8,'Use cases'!$E$2:$E$6000,"Pay") -> 0 | K8: =COUNTIFS('Use cases'!$C$2:$C$6000,A8,'Use cases'!$K$2:$K$6000,"*Handoff*") -> 7 | L8: =COUNTIFS('Use cases'!$C$2:$C$6000,A8,'Use cases'!$I$2:$I$6000,"(Gratifi starts it)*") -> 9 | M8: =COUNTIFS('Use cases'!$C$2:$C$6000,A8,'Use cases'!$K$2:$K$6000,"*NEW:*") -> 0 | N8: =IF(AND(G8>=6,H8>=2,I8>=2),"Covered","GAP") -> Covered
A9: FL-08 | B9: Flights | C9: Payment, refunds and invoices | D9: Points, card, refunds, tax invoices | E9: R360 core, bank | F9: In build | G9: =COUNTIF('Use cases'!$C$2:$C$6000,A9) -> 26 | H9: =COUNTIFS('Use cases'!$C$2:$C$6000,A9,'Use cases'!$H$2:$H$6000,"") -> 21 | I9: =G9-H9 -> 5 | J9: =COUNTIFS('Use cases'!$C$2:$C$6000,A9,'Use cases'!$E$2:$E$6000,"Pay") -> 15 | K9: =COUNTIFS('Use cases'!$C$2:$C$6000,A9,'Use cases'!$K$2:$K$6000,"*Handoff*") -> 3 | L9: =COUNTIFS('Use cases'!$C$2:$C$6000,A9,'Use cases'!$I$2:$I$6000,"(Gratifi starts it)*") -> 1 | M9: =COUNTIFS('Use cases'!$C$2:$C$6000,A9,'Use cases'!$K$2:$K$6000,"*NEW:*") -> 0 | N9: =IF(AND(G9>=6,H9>=2,I9>=2),"Covered","GAP") -> Covered
A10: ST-01 | B10: Stays | C10: Hotels | D10: Search, compare, book rooms | E10: TripSure 2.5M+ hotels, HotelBeds, WebBeds, Expedia MCP | F10: Hotels-first launch | G10: =COUNTIF('Use cases'!$C$2:$C$6000,A10) -> 36 | H10: =COUNTIFS('Use cases'!$C$2:$C$6000,A10,'Use cases'!$H$2:$H$6000,"") -> 29 | I10: =G10-H10 -> 7 | J10: =COUNTIFS('Use cases'!$C$2:$C$6000,A10,'Use cases'!$E$2:$E$6000,"Pay") -> 8 | K10: =COUNTIFS('Use cases'!$C$2:$C$6000,A10,'Use cases'!$K$2:$K$6000,"*Handoff*") -> 3 | L10: =COUNTIFS('Use cases'!$C$2:$C$6000,A10,'Use cases'!$I$2:$I$6000,"(Gratifi starts it)*") -> 2 | M10: =COUNTIFS('Use cases'!$C$2:$C$6000,A10,'Use cases'!$K$2:$K$6000,"*NEW:*") -> 4 | N10: =IF(AND(G10>=6,H10>=2,I10>=2),"Covered","GAP") -> Covered
A11: ST-02 | B11: Stays | C11: Apartments and villas | D11: Longer and group stays | E11: Suppliers to confirm | F11: To source | G11: =COUNTIF('Use cases'!$C$2:$C$6000,A11) -> 17 | H11: =COUNTIFS('Use cases'!$C$2:$C$6000,A11,'Use cases'!$H$2:$H$6000,"") -> 11 | I11: =G11-H11 -> 6 | J11: =COUNTIFS('Use cases'!$C$2:$C$6000,A11,'Use cases'!$E$2:$E$6000,"Pay") -> 3 | K11: =COUNTIFS('Use cases'!$C$2:$C$6000,A11,'Use cases'!$K$2:$K$6000,"*Handoff*") -> 6 | L11: =COUNTIFS('Use cases'!$C$2:$C$6000,A11,'Use cases'!$I$2:$I$6000,"(Gratifi starts it)*") -> 2 | M11: =COUNTIFS('Use cases'!$C$2:$C$6000,A11,'Use cases'!$K$2:$K$6000,"*NEW:*") -> 5 | N11: =IF(AND(G11>=6,H11>=2,I11>=2),"Covered","GAP") -> Covered
A12: ST-03 | B12: Stays | C12: Resorts and packages | D12: Stay plus flights or extras | E12: TripSure, partners | F12: To source | G12: =COUNTIF('Use cases'!$C$2:$C$6000,A12) -> 15 | H12: =COUNTIFS('Use cases'!$C$2:$C$6000,A12,'Use cases'!$H$2:$H$6000,"") -> 12 | I12: =G12-H12 -> 3 | J12: =COUNTIFS('Use cases'!$C$2:$C$6000,A12,'Use cases'!$E$2:$E$6000,"Pay") -> 3 | K12: =COUNTIFS('Use cases'!$C$2:$C$6000,A12,'Use cases'!$K$2:$K$6000,"*Handoff*") -> 4 | L12: =COUNTIFS('Use cases'!$C$2:$C$6000,A12,'Use cases'!$I$2:$I$6000,"(Gratifi starts it)*") -> 2 | M12: =COUNTIFS('Use cases'!$C$2:$C$6000,A12,'Use cases'!$K$2:$K$6000,"*NEW:*") -> 2 | N12: =IF(AND(G12>=6,H12>=2,I12>=2),"Covered","GAP") -> Covered
A13: ST-04 | B13: Stays | C13: Changes and cancellations | D13: Dates, rooms, guests, refunds | E13: Supplier rules | F13: In build | G13: =COUNTIF('Use cases'!$C$2:$C$6000,A13) -> 18 | H13: =COUNTIFS('Use cases'!$C$2:$C$6000,A13,'Use cases'!$H$2:$H$6000,"") -> 10 | I13: =G13-H13 -> 8 | J13: =COUNTIFS('Use cases'!$C$2:$C$6000,A13,'Use cases'!$E$2:$E$6000,"Pay") -> 1 | K13: =COUNTIFS('Use cases'!$C$2:$C$6000,A13,'Use cases'!$K$2:$K$6000,"*Handoff*") -> 8 | L13: =COUNTIFS('Use cases'!$C$2:$C$6000,A13,'Use cases'!$I$2:$I$6000,"(Gratifi starts it)*") -> 2 | M13: =COUNTIFS('Use cases'!$C$2:$C$6000,A13,'Use cases'!$K$2:$K$6000,"*NEW:*") -> 0 | N13: =IF(AND(G13>=6,H13>=2,I13>=2),"Covered","GAP") -> Covered
... A106: EN-06 | B106: Engagement and moments | C106: Feedback and preferences | D106: Ratings, likes, what not to show | E106: Gratifi | F106: To build | G106: =COUNTIF('Use cases'!$C$2:$C$6000,A106) -> 22 | H106: =COUNTIFS('Use cases'!$C$2:$C$6000,A106,'Use cases'!$H$2:$H$6000,"") -> 18 | I106: =G106-H106 -> 4 | J106: =COUNTIFS('Use cases'!$C$2:$C$6000,A106,'Use cases'!$E$2:$E$6000,"Pay") -> 0 | K106: =COUNTIFS('Use cases'!$C$2:$C$6000,A106,'Use cases'!$K$2:$K$6000,"*Handoff*") -> 4 | L106: =COUNTIFS('Use cases'!$C$2:$C$6000,A106,'Use cases'!$I$2:$I$6000,"(Gratifi starts it)*") -> 1 | M106: =COUNTIFS('Use cases'!$C$2:$C$6000,A106,'Use cases'!$K$2:$K$6000,"*NEW:*") -> 4 | N106: =IF(AND(G106>=6,H106>=2,I106>=2),"Covered","GAP") -> Covered
A108: To add a product or service: add a row above this line with a new Item ID and copy the formulas in G to N. It shows GAP until its use cases exist.

Sheet Use cases
A1: ID | B1: Category | C1: Item ID | D1: Item | E1: Stage | F1: Job | G1: Constraint | H1: Exception | I1: Customer says | J1: Gratifi does | K1: UI blocks (kit) | L1: Rules: systems decide | M1: Market notes | N1: Volume | O1: Value | P1: Risk | Q1: Core path | R1: Priority | S1: Wave
A2: FL-01-001 | B2: Flights | C2: FL-01 | D2: One-way and return flights | E2: Discover | F2: Find somewhere to go | G2: Budget | I2: Somewhere warm in October for under 40,000 points | J2: Suggests 3 places the points cover, with flight price and weather | K2: Answer, Rail, Polaroid, Price | L2: Only places with live fares under the budget | N2: 4 | O2: 3 | P2: 1 | R2: =IF(OR(N2="",P2=""),"",ROUND(N2*O2/P2,1)) -> 12 | S2: =IF(R2="","",IF(Q2="Y",1,IF(P2>='Read me'!$B$16,3,IF(AND(R2>='Read me'!$B$14,P2<='Read me'!$B$15),1,2)))) -> 1
A3: FL-01-002 | B3: Flights | C3: FL-01 | D3: One-way and return flights | E3: Discover | F3: Find somewhere to go | G3: Dates fixed | I3: Where can I go for the long weekend? | J3: Finds direct flights for those dates, shortest first | K3: Answer, Rail, FlightCard | L3: Uses the bank holiday calendar for the market | M3: Holiday calendars differ: bank holidays (UK, EU), Diwali/Deepavali (IN, SG, MY), Eid/Hari Raya (AE, MY, SG, IN), Chinese New Year (SG, MY) | N3: 4 | O3: 3 | P3: 1 | R3: =IF(OR(N3="",P3=""),"",ROUND(N3*O3/P3,1)) -> 12 | S3: =IF(R3="","",IF(Q3="Y",1,IF(P3>='Read me'!$B$16,3,IF(AND(R3>='Read me'!$B$14,P3<='Read me'!$B$15),1,2)))) -> 1
A4: FL-01-003 | B4: Flights | C4: FL-01 | D4: One-way and return flights | E4: Discover | F4: Find somewhere to go | G4: Points only | I4: What can I get with my points alone? | J4: Shows trips fully covered by the balance | K4: Answer, Dial, Rail | L4: Balance and point value from the bank | N4: 4 | O4: 4 | P4: 1 | R4: =IF(OR(N4="",P4=""),"",ROUND(N4*O4/P4,1)) -> 16 | S4: =IF(R4="","",IF(Q4="Y",1,IF(P4>='Read me'!$B$16,3,IF(AND(R4>='Read me'!$B$14,P4<='Read me'!$B$15),1,2)))) -> 1
A5: FL-01-004 | B5: Flights | C5: FL-01 | D5: One-way and return flights | E5: Discover | F5: Find somewhere to go | G5: Travelling with kids | I5: Somewhere easy with a toddler, short flight | J5: Filters to under 3 hours, direct, family-friendly stays | K5: Answer, Rail, Chips | L5: Flight time cap is a hard filter | N5: 3 | O5: 3 | P5: 1 | R5: =IF(OR(N5="",P5=""),"",ROUND(N5*O5/P5,1)) -> 9 | S5: =IF(R5="","",IF(Q5="Y",1,IF(P5>='Read me'!$B$16,3,IF(AND(R5>='Read me'!$B$14,P5<='Read me'!$B$15),1,2)))) -> 1
A6: FL-01-005 | B6: Flights | C6: FL-01 | D6: One-way and return flights | E6: Discover | F6: Get a price alert | G6: Route known | I6: Tell me if London to Lisbon drops under £150 | J6: Sets an alert and confirms the threshold | K6: Toast, Toggle | L6: Alert fires on supplier price, not an estimate | N6: 3 | O6: 2 | P6: 1 | R6: =IF(OR(N6="",P6=""),"",ROUND(N6*O6/P6,1)) -> 6 | S6: =IF(R6="","",IF(Q6="Y",1,IF(P6>='Read me'!$B$16,3,IF(AND(R6>='Read me'!$B$14,P6<='Read me'!$B$15),1,2)))) -> 1
A7: FL-01-006 | B7: Flights | C7: FL-01 | D7: One-way and return flights | E7: Discover | F7: Get told about a deal | G7: Card benefit | I7: (Gratifi starts it) | J7: Moment: a card offer on a route the customer flies often | K7: StickyNote, OfferCard | L7: Only offers the customer is eligible for; marketing consent checked | M7: Consent rules differ: UK GDPR/PECR, EU GDPR, India DPDP Act, Singapore PDPA, Malaysia PDPA, UAE PDPL | N7: 3 | O7: 4 | P7: 2 | R7: =IF(OR(N7="",P7=""),"",ROUND(N7*O7/P7,1)) -> 6 | S7: =IF(R7="","",IF(Q7="Y",1,IF(P7>='Read me'!$B$16,3,IF(AND(R7>='Read me'!$B$14,P7<='Read me'!$B$15),1,2)))) -> 1
A8: FL-01-007 | B8: Flights | C8: FL-01 | D8: One-way and return flights | E8: Discover | F8: Plan around an event | G8: Date fixed by event | I8: Flights for the F1 weekend | J8: Finds flights and warns about peak prices | K8: Answer, PriceCalendar, StateCard | L8: Event dates from content partner | N8: 2 | O8: 3 | P8: 1 | R8: =IF(OR(N8="",P8=""),"",ROUND(N8*O8/P8,1)) -> 6 | S8: =IF(R8="","",IF(Q8="Y",1,IF(P8>='Read me'!$B$16,3,IF(AND(R8>='Read me'!$B$14,P8<='Read me'!$B$15),1,2)))) -> 1
A9: FL-01-008 | B9: Flights | C9: FL-01 | D9: One-way and return flights | E9: Discover | F9: Compare two places | G9: Undecided | I9: Lisbon or Porto for 3 nights? | J9: Side-by-side of flight, hotel and total in points | K9: Compare | L9: Totals include taxes | N9: 2 | O9: 3 | P9: 1 | R9: =IF(OR(N9="",P9=""),"",ROUND(N9*O9/P9,1)) -> 6 | S9: =IF(R9="","",IF(Q9="Y",1,IF(P9>='Read me'!$B$16,3,IF(AND(R9>='Read me'!$B$14,P9<='Read me'!$B$15),1,2)))) -> 1
A10: FL-01-009 | B10: Flights | C10: FL-01 | D10: One-way and return flights | E10: Search | F10: Book a return flight | G10: Dates fixed | I10: Lisbon for two, 16 to 18 October | J10: Three best options with a recommendation and the reason | K10: YouSaid, Steps, Answer, Rail, FlightCard, Suggestions | L10: Supplier fares only; the recommendation reason must be a stated fact | N10: 5 | O10: 5 | P10: 2 | Q10: Y | R10: =IF(OR(N10="",P10=""),"",ROUND(N10*O10/P10,1)) -> 12.5 | S10: =IF(R10="","",IF(Q10="Y",1,IF(P10>='Read me'!$B$16,3,IF(AND(R10>='Read me'!$B$14,P10<='Read me'!$B$15),1,2)))) -> 1
A11: FL-01-010 | B11: Flights | C11: FL-01 | D11: One-way and return flights | E11: Search | F11: Book a return flight | G11: Flexible dates | I11: Cheapest week in October to Lisbon | J11: Price calendar with the cheapest days marked | K11: PriceCalendar | L11: Calendar prices are cached; confirm live before pay | M11: Week starts Sunday in IN and SG, Monday elsewhere | N11: 5 | O11: 4 | P11: 2 | Q11: Y | R11: =IF(OR(N11="",P11=""),"",ROUND(N11*O11/P11,1)) -> 10 | S11: =IF(R11="","",IF(Q11="Y",1,IF(P11>='Read me'!$B$16,3,IF(AND(R11>='Read me'!$B$14,P11<='Read me'!$B$15),1,2)))) -> 1
A12: FL-01-011 | B12: Flights | C12: FL-01 | D12: One-way and return flights | E12: Search | F12: Book a one-way flight | G12: Dates fixed | I12: One way to Dubai on Friday | J12: Results for one-way only | K12: FlightCard, Rail | N12: 4 | O12: 4 | P12: 1 | R12: =IF(OR(N12="",P12=""),"",ROUND(N12*O12/P12,1)) -> 16 | S12: =IF(R12="","",IF(Q12="Y",1,IF(P12>='Read me'!$B$16,3,IF(AND(R12>='Read me'!$B$14,P12<='Read me'!$B$15),1,2)))) -> 1
A13: FL-01-012 | B13: Flights | C13: FL-01 | D13: One-way and return flights | E13: Search | F13: Search with filters | G13: Direct only | I13: Only direct | J13: Filters and says how many are left | K13: FilterBar, Chips | N13: 5 | O13: 3 | P13: 1 | R13: =IF(OR(N13="",P13=""),"",ROUND(N13*O13/P13,1)) -> 15 | S13: =IF(R13="","",IF(Q13="Y",1,IF(P13>='Read me'!$B$16,3,IF(AND(R13>='Read me'!$B$14,P13<='Read me'!$B$15),1,2)))) -> 1
A14: FL-01-013 | B14: Flights | C14: FL-01 | D14: One-way and return flights | E14: Search | F14: Search with filters | G14: Time of day | I14: Nothing before 9am | J14: Filters by departure time | K14: FilterBar | N14: 4 | O14: 3 | P14: 1 | R14: =IF(OR(N14="",P14=""),"",ROUND(N14*O14/P14,1)) -> 12 | S14: =IF(R14="","",IF(Q14="Y",1,IF(P14>='Read me'!$B$16,3,IF(AND(R14>='Read me'!$B$14,P14<='Read me'!$B$15),1,2)))) -> 1
A15: FL-01-014 | B15: Flights | C15: FL-01 | D15: One-way and return flights | E15: Search | F15: Search with filters | G15: Airline preference | I15: Only airlines where I earn miles | J15: Filters to airlines linked to the customer's schemes | K15: FilterBar, Badge | L15: Frequent flyer numbers from the profile | N15: 3 | O15: 3 | P15: 1 | R15: =IF(OR(N15="",P15=""),"",ROUND(N15*O15/P15,1)) -> 9 | S15: =IF(R15="","",IF(Q15="Y",1,IF(P15>='Read me'!$B$16,3,IF(AND(R15>='Read me'!$B$14,P15<='Read me'!$B$15),1,2)))) -> 1
A16: FL-01-015 | B16: Flights | C16: FL-01 | D16: One-way and return flights | E16: Search | F16: Search with filters | G16: Bag included | I16: Must include a checked bag | J16: Filters to fares with a checked bag, shows true total | K16: FilterBar, FareFamilies | L16: Total must include the bag | N16: 4 | O16: 3 | P16: 1 | R16: =IF(OR(N16="",P16=""),"",ROUND(N16*O16/P16,1)) -> 12 | S16: =IF(R16="","",IF(Q16="Y",1,IF(P16>='Read me'!$B$16,3,IF(AND(R16>='Read me'!$B$14,P16<='Read me'!$B$15),1,2)))) -> 1
A17: FL-01-016 | B17: Flights | C17: FL-01 | D17: One-way and return flights | E17: Search | F17: Search nearby airports | G17: City, not airport | I17: Any London airport | J17: Searches all airports for the city | K17: FlightCard | L17: Airport groups per city | N17: 4 | O17: 3 | P17: 1 | R17: =IF(OR(N17="",P17=""),"",ROUND(N17*O17/P17,1)) -> 12 | S17: =IF(R17="","",IF(Q17="Y",1,IF(P17>='Read me'!$B$16,3,IF(AND(R17>='Read me'!$B$14,P17<='Read me'!$B$15),1,2)))) -> 1
A18: FL-01-017 | B18: Flights | C18: FL-01 | D18: One-way and return flights | E18: Search | F18: Search by voice | G18: Hands busy | I18: (spoken) Flights to Goa next weekend | J18: Transcribes, confirms understanding, searches | K18: AskBar (listening), YouSaid | L18: Shows what it heard before acting | M18: Voice in English first; Hindi, Arabic, Malay later | N18: 3 | O18: 3 | P18: 2 | R18: =IF(OR(N18="",P18=""),"",ROUND(N18*O18/P18,1)) -> 4.5 | S18: =IF(R18="","",IF(Q18="Y",1,IF(P18>='Read me'!$B$16,3,IF(AND(R18>='Read me'!$B$14,P18<='Read me'!$B$15),1,2)))) -> 2
A19: FL-01-018 | B19: Flights | C19: FL-01 | D19: One-way and return flights | E19: Search | F19: Search premium cabins | G19: Business class | I19: Business class to Singapore | J19: Shows business fares and points cost | K19: FlightCard, FareFamilies | N19: 2 | O19: 5 | P19: 1 | R19: =IF(OR(N19="",P19=""),"",ROUND(N19*O19/P19,1)) -> 10 | S19: =IF(R19="","",IF(Q19="Y",1,IF(P19>='Read me'!$B$16,3,IF(AND(R19>='Read me'!$B$14,P19<='Read me'!$B$15),1,2)))) -> 1
A20: FL-01-019 | B20: Flights | C20: FL-01 | D20: One-way and return flights | E20: Search | F20: Search with points and cash | G20: Budget in points | I20: Use no more than 20,000 points | J20: Prices each option as points plus cash | K20: PointsSlider, Price | L20: Point value from the bank | N20: 4 | O20: 4 | P20: 1 | R20: =IF(OR(N20="",P20=""),"",ROUND(N20*O20/P20,1)) -> 16 | S20: =IF(R20="","",IF(Q20="Y",1,IF(P20>='Read me'!$B$16,3,IF(AND(R20>='Read me'!$B$14,P20<='Read me'!$B$15),1,2)))) -> 1
A21: FL-01-020 | B21: Flights | C21: FL-01 | D21: One-way and return flights | E21: Search | F21: Nothing found | G21: Too strict | H21: No results | I21: Direct, before 9am, under £100 | J21: Says which filter blocks it and offers the nearest options | K21: StateCard (empty) | L21: Never invents a flight | N21: 3 | O21: 3 | P21: 1 | R21: =IF(OR(N21="",P21=""),"",ROUND(N21*O21/P21,1)) -> 9 | S21: =IF(R21="","",IF(Q21="Y",1,IF(P21>='Read me'!$B$16,3,IF(AND(R21>='Read me'!$B$14,P21<='Read me'!$B$15),1,2)))) -> 1
A22: FL-01-021 | B22: Flights | C22: FL-01 | D22: One-way and return flights | E22: Search | F22: Search fails | G22: Supplier down | H22: Timeout | I22: (any search) | J22: Says the airline is not answering, nothing was booked, try again | K22: StateCard (error) | L22: Retry with backoff; switch supplier if available | N22: 2 | O22: 2 | P22: 2 | Q22: Y | R22: =IF(OR(N22="",P22=""),"",ROUND(N22*O22/P22,1)) -> 2 | S22: =IF(R22="","",IF(Q22="Y",1,IF(P22>='Read me'!$B$16,3,IF(AND(R22>='Read me'!$B$14,P22<='Read me'!$B$15),1,2)))) -> 1
A23: FL-01-022 | B23: Flights | C23: FL-01 | D23: One-way and return flights | E23: Search | F23: Book last minute | G23: Today | I23: Next flight to Edinburgh | J23: Shows flights leaving soonest with check-in cut-off | K23: FlightCard, Status | L23: Cut-off times per airline | N23: 2 | O23: 4 | P23: 2 | R23: =IF(OR(N23="",P23=""),"",ROUND(N23*O23/P23,1)) -> 4 | S23: =IF(R23="","",IF(Q23="Y",1,IF(P23>='Read me'!$B$16,3,IF(AND(R23>='Read me'!$B$14,P23<='Read me'!$B$15),1,2)))) -> 2
A24: FL-01-023 | B24: Flights | C24: FL-01 | D24: One-way and return flights | E24: Choose | F24: Choose between flights | G24: Two close options | I24: Which is better, the 7am or the 11am? | J24: Compares on what differs: time, bag, price, points back | K24: Compare | L24: Only facts from the fares | N24: 4 | O24: 4 | P24: 1 | R24: =IF(OR(N24="",P24=""),"",ROUND(N24*O24/P24,1)) -> 16 | S24: =IF(R24="","",IF(Q24="Y",1,IF(P24>='Read me'!$B$16,3,IF(AND(R24>='Read me'!$B$14,P24<='Read me'!$B$15),1,2)))) -> 1
A25: FL-01-024 | B25: Flights | C25: FL-01 | D25: One-way and return flights | E25: Choose | F25: Understand a fare | G25: Unsure what is included | I25: Does Light include a bag? | J25: Shows fare families, ticked and greyed | K25: FareFamilies | L25: Fare rules from the supplier, word for word in the source | N25: 5 | O25: 4 | P25: 2 | Q25: Y | R25: =IF(OR(N25="",P25=""),"",ROUND(N25*O25/P25,1)) -> 10 | S25: =IF(R25="","",IF(Q25="Y",1,IF(P25>='Read me'!$B$16,3,IF(AND(R25>='Read me'!$B$14,P25<='Read me'!$B$15),1,2)))) -> 1
A26: FL-01-025 | B26: Flights | C26: FL-01 | D26: One-way and return flights | E26: Choose | F26: Understand change rules | G26: Might change plans | I26: Can I change the date later? | J26: Plain-words fare rules: free, fee, not possible | K26: FareRules | L26: Rules from fare; never guessed | N26: 4 | O26: 4 | P26: 3 | R26: =IF(OR(N26="",P26=""),"",ROUND(N26*O26/P26,1)) -> 5.3 | S26: =IF(R26="","",IF(Q26="Y",1,IF(P26>='Read me'!$B$16,3,IF(AND(R26>='Read me'!$B$14,P26<='Read me'!$B$15),1,2)))) -> 2
A27: FL-01-026 | B27: Flights | C27: FL-01 | D27: One-way and return flights | E27: Choose | F27: See the full journey | G27: Connection | I27: How long is the stop in Porto? | J27: Itinerary with layover; tight ones in amber | K27: Itinerary | L27: Minimum connection time per airport | N27: 3 | O27: 3 | P27: 2 | R27: =IF(OR(N27="",P27=""),"",ROUND(N27*O27/P27,1)) -> 4.5 | S27: =IF(R27="","",IF(Q27="Y",1,IF(P27>='Read me'!$B$16,3,IF(AND(R27>='Read me'!$B$14,P27<='Read me'!$B$15),1,2)))) -> 2
A28: FL-01-027 | B28: Flights | C28: FL-01 | D28: One-way and return flights | E28: Choose | F28: See the plane | G28: Comfort | I28: What plane is it? | J28: Aircraft type and seat pitch if known | K28: Itinerary, Meta | N28: 2 | O28: 2 | P28: 1 | R28: =IF(OR(N28="",P28=""),"",ROUND(N28*O28/P28,1)) -> 4 | S28: =IF(R28="","",IF(Q28="Y",1,IF(P28>='Read me'!$B$16,3,IF(AND(R28>='Read me'!$B$14,P28<='Read me'!$B$15),1,2)))) -> 2
A29: FL-01-028 | B29: Flights | C29: FL-01 | D29: One-way and return flights | E29: Choose | F29: Choose travellers | G29: Children | I29: Two adults and a 3 year old | J29: Sets travellers with correct age bands | K29: Travellers | L29: Age on the day of travel; airline bands | N29: 4 | O29: 3 | P29: 2 | R29: =IF(OR(N29="",P29=""),"",ROUND(N29*O29/P29,1)) -> 6 | S29: =IF(R29="","",IF(Q29="Y",1,IF(P29>='Read me'!$B$16,3,IF(AND(R29>='Read me'!$B$14,P29<='Read me'!$B$15),1,2)))) -> 1
A30: FL-01-029 | B30: Flights | C30: FL-01 | D30: One-way and return flights | E30: Choose | F30: Choose travellers | G30: Infant on lap | I30: Plus a baby | J30: Adds infant, one per adult | K30: Travellers | L30: Infants never exceed adults | N30: 3 | O30: 3 | P30: 2 | R30: =IF(OR(N30="",P30=""),"",ROUND(N30*O30/P30,1)) -> 4.5 | S30: =IF(R30="","",IF(Q30="Y",1,IF(P30>='Read me'!$B$16,3,IF(AND(R30>='Read me'!$B$14,P30<='Read me'!$B$15),1,2)))) -> 2
A31: FL-01-030 | B31: Flights | C31: FL-01 | D31: One-way and return flights | E31: Choose | F31: Choose travellers | G31: Travelling alone as a minor | I31: My daughter is flying alone, she's 13 | J31: Explains the airline's unaccompanied minor service and hands over | K31: StateCard, Handoff | L31: Unaccompanied minors always go to a person | N31: 1 | O31: 3 | P31: 5 | R31: =IF(OR(N31="",P31=""),"",ROUND(N31*O31/P31,1)) -> 0.6 | S31: =IF(R31="","",IF(Q31="Y",1,IF(P31>='Read me'!$B$16,3,IF(AND(R31>='Read me'!$B$14,P31<='Read me'!$B$15),1,2)))) -> 3
A32: FL-01-031 | B32: Flights | C32: FL-01 | D32: One-way and return flights | E32: Choose | F32: Price changed | G32: Between search and choose | H32: Fare rose | I32: (taps a flight) | J32: Shows old and new price, asks to continue | K32: StateCard (price) | L32: Never book at a higher price without a new yes | N32: 3 | O32: 3 | P32: 3 | Q32: Y | R32: =IF(OR(N32="",P32=""),"",ROUND(N32*O32/P32,1)) -> 3 | S32: =IF(R32="","",IF(Q32="Y",1,IF(P32>='Read me'!$B$16,3,IF(AND(R32>='Read me'!$B$14,P32<='Read me'!$B$15),1,2)))) -> 1
A33: FL-01-032 | B33: Flights | C33: FL-01 | D33: One-way and return flights | E33: Choose | F33: Sold out | G33: Last seats | H33: Fare gone | I33: (taps a flight) | J33: Says it has gone and offers the next best | K33: StateCard (soldout) | N33: 3 | O33: 3 | P33: 2 | Q33: Y | R33: =IF(OR(N33="",P33=""),"",ROUND(N33*O33/P33,1)) -> 4.5 | S33: =IF(R33="","",IF(Q33="Y",1,IF(P33>='Read me'!$B$16,3,IF(AND(R33>='Read me'!$B$14,P33<='Read me'!$B$15),1,2)))) -> 1
A34: FL-01-033 | B34: Flights | C34: FL-01 | D34: One-way and return flights | E34: Choose | F34: Hold a fare | G34: Deciding | I34: Can you hold this for a day? | J34: Offers fare hold if the airline sells it | K34: StateCard, ConfirmSheet | L34: Hold price and time from the airline | N34: 2 | O34: 3 | P34: 3 | R34: =IF(OR(N34="",P34=""),"",ROUND(N34*O34/P34,1)) -> 2 | S34: =IF(R34="","",IF(Q34="Y",1,IF(P34>='Read me'!$B$16,3,IF(AND(R34>='Read me'!$B$14,P34<='Read me'!$B$15),1,2)))) -> 2
A35: FL-01-034 | B35: Flights | C35: FL-01 | D35: One-way and return flights | E35: Choose | F35: Check the carbon | G35: Green choice | I35: Which one is lower carbon? | J35: Shows estimated emissions per option | K35: Compare | L35: Estimate from a named source | M35: Carbon disclosure rules vary; EU strictest | N35: 1 | O35: 2 | P35: 2 | R35: =IF(OR(N35="",P35=""),"",ROUND(N35*O35/P35,1)) -> 1 | S35: =IF(R35="","",IF(Q35="Y",1,IF(P35>='Read me'!$B$16,3,IF(AND(R35>='Read me'!$B$14,P35<='Read me'!$B$15),1,2)))) -> 2
A36: FL-02-001 | B36: Flights | C36: FL-02 | D36: Multi-city, open jaw, groups | E36: Search | F36: Book a multi-city trip | G36: Several stops | I36: London to Lisbon, then Porto, then home | J36: Builds the legs and prices them together and separately | K36: Itinerary, Compare | L36: Separate tickets flagged: missed connections not protected | N36: 2 | O36: 4 | P36: 3 | R36: =IF(OR(N36="",P36=""),"",ROUND(N36*O36/P36,1)) -> 2.7 | S36: =IF(R36="","",IF(Q36="Y",1,IF(P36>='Read me'!$B$16,3,IF(AND(R36>='Read me'!$B$14,P36<='Read me'!$B$15),1,2)))) -> 2
A37: FL-02-002 | B37: Flights | C37: FL-02 | D37: Multi-city, open jaw, groups | E37: Search | F37: Search for a group | G37: 5 or more | I37: Flights for 8 of us | J37: Checks seat availability for 8, offers group fare route | K37: Travellers, StateCard, Handoff | L37: Over 9 passengers goes to group desk | N37: 2 | O37: 4 | P37: 3 | R37: =IF(OR(N37="",P37=""),"",ROUND(N37*O37/P37,1)) -> 2.7 | S37: =IF(R37="","",IF(Q37="Y",1,IF(P37>='Read me'!$B$16,3,IF(AND(R37>='Read me'!$B$14,P37<='Read me'!$B$15),1,2)))) -> 2
A38: FL-02-003 | B38: Flights | C38: FL-02 | D38: Multi-city, open jaw, groups | E38: Search | F38: Book a return flight | G38: Open jaw | I38: Fly into Lisbon, back from Porto | J38: Prices the open jaw as one trip | K38: Itinerary, FlightCard | L38: Fare construction by supplier | N38: 2 | O38: 3 | P38: 2 | R38: =IF(OR(N38="",P38=""),"",ROUND(N38*O38/P38,1)) -> 3 | S38: =IF(R38="","",IF(Q38="Y",1,IF(P38>='Read me'!$B$16,3,IF(AND(R38>='Read me'!$B$14,P38<='Read me'!$B$15),1,2)))) -> 2
A39: FL-02-004 | B39: Flights | C39: FL-02 | D39: Multi-city, open jaw, groups | E39: Search | F39: Book for someone else | G39: Gift trip | I39: Book flights for my parents | J39: Captures their names, pays from my points | K39: Travellers, PayWith | L39: Names must match passports | N39: 2 | O39: 4 | P39: 3 | R39: =IF(OR(N39="",P39=""),"",ROUND(N39*O39/P39,1)) -> 2.7 | S39: =IF(R39="","",IF(Q39="Y",1,IF(P39>='Read me'!$B$16,3,IF(AND(R39>='Read me'!$B$14,P39<='Read me'!$B$15),1,2)))) -> 2
A40: FL-02-005 | B40: Flights | C40: FL-02 | D40: Multi-city, open jaw, groups | E40: Search | F40: Book a multi-city trip | G40: Stopover | I40: London to Singapore with 3 nights in Dubai on the way | J40: Prices the stopover as one ticket and shows the extra cost of the stop | K40: Itinerary, FlightCard, PriceLines | L40: Fare construction by supplier; stopover rules from the fare | N40: 2 | O40: 4 | P40: 2 | R40: =IF(OR(N40="",P40=""),"",ROUND(N40*O40/P40,1)) -> 4 | S40: =IF(R40="","",IF(Q40="Y",1,IF(P40>='Read me'!$B$16,3,IF(AND(R40>='Read me'!$B$14,P40<='Read me'!$B$15),1,2)))) -> 2
...

Sheet Kit gaps
A1: Block to build | B1: Use cases needing it | C1: Items | D1: Also called
A2: ClaimTracker | B2: =COUNTIF('Use cases'!$K$2:$K$6000,"*NEW: ClaimTracker,*")+COUNTIF('Use cases'!$K$2:$K$6000,"*NEW: ClaimTracker")+COUNTIF('Use cases'!$K$2:$K$6000,"*NEW: ClaimTracker *") -> 75 | C2: BE-02, BE-03, BE-04, BE-05, BE-06, BE-07, BS-03, BS-04, BS-05, BS-07, CO-01, CO-02, CO-03, CO-04, DN-04, EN-03, EN-05, EN-06, SH-05, ST-05, TD-01, TD-03 | D2: RequestTracker, ApplicationTracker, MissingPointsClaim
A3: ServiceCard | B3: =COUNTIF('Use cases'!$K$2:$K$6000,"*NEW: ServiceCard,*")+COUNTIF('Use cases'!$K$2:$K$6000,"*NEW: ServiceCard")+COUNTIF('Use cases'!$K$2:$K$6000,"*NEW: ServiceCard *") -> 29 | C3: AP-01, AP-02, AP-04, AP-05, AP-06
A4: SubscriptionCard | B4: =COUNTIF('Use cases'!$K$2:$K$6000,"*NEW: SubscriptionCard,*")+COUNTIF('Use cases'!$K$2:$K$6000,"*NEW: SubscriptionCard")+COUNTIF('Use cases'!$K$2:$K$6000,"*NEW: SubscriptionCard *") -> 28 | C4: SB-01, SB-02, SB-03, SB-04, SB-05, SB-06
A5: Upload | B5: =COUNTIF('Use cases'!$K$2:$K$6000,"*NEW: Upload,*")+COUNTIF('Use cases'!$K$2:$K$6000,"*NEW: Upload")+COUNTIF('Use cases'!$K$2:$K$6000,"*NEW: Upload *") -> 26 | C5: BE-02, BE-03, BE-04, BS-08, GC-05, QC-01, QC-02, QC-03, SH-02, SH-03, SH-06, SH-07, TD-01, TD-03 | D5: PhotoUpload, EvidenceUpload, DocumentUpload, ReceiptCapture
A6: Basket | B6: =COUNTIF('Use cases'!$K$2:$K$6000,"*NEW: Basket,*")+COUNTIF('Use cases'!$K$2:$K$6000,"*NEW: Basket")+COUNTIF('Use cases'!$K$2:$K$6000,"*NEW: Basket *") -> 25 | C6: QC-01, QC-02, QC-03, SH-03
A7: CardControls | B7: =COUNTIF('Use cases'!$K$2:$K$6000,"*NEW: CardControls,*")+COUNTIF('Use cases'!$K$2:$K$6000,"*NEW: CardControls")+COUNTIF('Use cases'!$K$2:$K$6000,"*NEW: CardControls *") -> 25 | C7: BS-04, BS-06, BS-08
A8: RestaurantCard | B8: =COUNTIF('Use cases'!$K$2:$K$6000,"*NEW: RestaurantCard,*")+COUNTIF('Use cases'!$K$2:$K$6000,"*NEW: RestaurantCard")+COUNTIF('Use cases'!$K$2:$K$6000,"*NEW: RestaurantCard *") -> 21 | C8: CO-01, DN-01, DN-02, ET-04, QC-03
A9: Map | B9: =COUNTIF('Use cases'!$K$2:$K$6000,"*NEW: Map,*")+COUNTIF('Use cases'!$K$2:$K$6000,"*NEW: Map")+COUNTIF('Use cases'!$K$2:$K$6000,"*NEW: Map *") -> 18 | C9: AP-01, AP-04, AP-05, AP-06, DN-01, DN-03, EX-01, EX-02, GT-02, GT-04, ST-01 | D9: MapView, TerminalMap
A10: VoucherCode | B10: =COUNTIF('Use cases'!$K$2:$K$6000,"*NEW: VoucherCode,*")+COUNTIF('Use cases'!$K$2:$K$6000,"*NEW: VoucherCode")+COUNTIF('Use cases'!$K$2:$K$6000,"*NEW: VoucherCode *") -> 17 | C10: GC-01, GC-02, GC-04, SB-01, SB-02, SB-03
A11: DeliveryTracker | B11: =COUNTIF('Use cases'!$K$2:$K$6000,"*NEW: DeliveryTracker,*")+COUNTIF('Use cases'!$K$2:$K$6000,"*NEW: DeliveryTracker")+COUNTIF('Use cases'!$K$2:$K$6000,"*NEW: DeliveryTracker *") -> 16 | C11: CO-02, QC-01, QC-02, QC-03, SH-06, SH-07
A12: RightsGuide | B12: =COUNTIF('Use cases'!$K$2:$K$6000,"*NEW: RightsGuide,*")+COUNTIF('Use cases'!$K$2:$K$6000,"*NEW: RightsGuide")+COUNTIF('Use cases'!$K$2:$K$6000,"*NEW: RightsGuide *") -> 16 | C12: BE-07
A13: AlertSettings | B13: =COUNTIF('Use cases'!$K$2:$K$6000,"*NEW: AlertSettings,*")+COUNTIF('Use cases'!$K$2:$K$6000,"*NEW: AlertSettings")+COUNTIF('Use cases'!$K$2:$K$6000,"*NEW: AlertSettings *") -> 16 | C13: EN-01, EN-02 | D13: QuietHours
A14: TicketWallet | B14: =COUNTIF('Use cases'!$K$2:$K$6000,"*NEW: TicketWallet,*")+COUNTIF('Use cases'!$K$2:$K$6000,"*NEW: TicketWallet")+COUNTIF('Use cases'!$K$2:$K$6000,"*NEW: TicketWallet *") -> 14 | C14: AP-02, AP-06, DN-03, ET-01, ET-02, ET-03, ET-05, EX-01, EX-03 | D14: ServicePass
A15: ConciergeBrief | B15: =COUNTIF('Use cases'!$K$2:$K$6000,"*NEW: ConciergeBrief,*")+COUNTIF('Use cases'!$K$2:$K$6000,"*NEW: ConciergeBrief")+COUNTIF('Use cases'!$K$2:$K$6000,"*NEW: ConciergeBrief *") -> 14 | C15: CO-01, CO-02, CO-03, CO-04
A16: CharityCard | B16: =COUNTIF('Use cases'!$K$2:$K$6000,"*NEW: CharityCard,*")+COUNTIF('Use cases'!$K$2:$K$6000,"*NEW: CharityCard")+COUNTIF('Use cases'!$K$2:$K$6000,"*NEW: CharityCard *") -> 14 | C16: CH-01, CH-02, CH-03
A17: GreeterCard | B17: =COUNTIF('Use cases'!$K$2:$K$6000,"*NEW: GreeterCard,*")+COUNTIF('Use cases'!$K$2:$K$6000,"*NEW: GreeterCard")+COUNTIF('Use cases'!$K$2:$K$6000,"*NEW: GreeterCard *") -> 13 | C17: AP-01, AP-04, AP-06, GT-02
A18: PolicyCard | B18: =COUNTIF('Use cases'!$K$2:$K$6000,"*NEW: PolicyCard,*")+COUNTIF('Use cases'!$K$2:$K$6000,"*NEW: PolicyCard")+COUNTIF('Use cases'!$K$2:$K$6000,"*NEW: PolicyCard *") -> 13 | C18: TD-03
A19: InstalmentPlan | B19: =COUNTIF('Use cases'!$K$2:$K$6000,"*NEW: InstalmentPlan,*")+COUNTIF('Use cases'!$K$2:$K$6000,"*NEW: InstalmentPlan")+COUNTIF('Use cases'!$K$2:$K$6000,"*NEW: InstalmentPlan *") -> 12 | C19: BE-06, BS-03, BS-05, CO-04, SH-01, SH-03 | D19: PlanTable, PaymentSchedule
A20: ChallengeCard | B20: =COUNTIF('Use cases'!$K$2:$K$6000,"*NEW: ChallengeCard,*")+COUNTIF('Use cases'!$K$2:$K$6000,"*NEW: ChallengeCard")+COUNTIF('Use cases'!$K$2:$K$6000,"*NEW: ChallengeCard *") -> 12 | C20: EN-03
A21: SupportLines | B21: =COUNTIF('Use cases'!$K$2:$K$6000,"*NEW: SupportLines,*")+COUNTIF('Use cases'!$K$2:$K$6000,"*NEW: SupportLines")+COUNTIF('Use cases'!$K$2:$K$6000,"*NEW: SupportLines *") -> 12 | C21: BS-04, BS-05, BS-06, BS-07, BS-08
A22: TrainCard | B22: =COUNTIF('Use cases'!$K$2:$K$6000,"*NEW: TrainCard,*")+COUNTIF('Use cases'!$K$2:$K$6000,"*NEW: TrainCard")+COUNTIF('Use cases'!$K$2:$K$6000,"*NEW: TrainCard *") -> 11 | C22: GT-03
A23: VenueSeatMap | B23: =COUNTIF('Use cases'!$K$2:$K$6000,"*NEW: VenueSeatMap,*")+COUNTIF('Use cases'!$K$2:$K$6000,"*NEW: VenueSeatMap")+COUNTIF('Use cases'!$K$2:$K$6000,"*NEW: VenueSeatMap *") -> 11 | C23: ET-01, ET-02, ET-03, ET-04, ET-05
A24: ReturnFlow | B24: =COUNTIF('Use cases'!$K$2:$K$6000,"*NEW: ReturnFlow,*")+COUNTIF('Use cases'!$K$2:$K$6000,"*NEW: ReturnFlow")+COUNTIF('Use cases'!$K$2:$K$6000,"*NEW: ReturnFlow *") -> 11 | C24: SH-02, SH-03, SH-06, SH-07
A25: IssuePicker | B25: =COUNTIF('Use cases'!$K$2:$K$6000,"*NEW: IssuePicker,*")+COUNTIF('Use cases'!$K$2:$K$6000,"*NEW: IssuePicker")+COUNTIF('Use cases'!$K$2:$K$6000,"*NEW: IssuePicker *") -> 10 | C25: QC-01, QC-02, QC-03, SH-07
A26: RiskDisclosure | B26: =COUNTIF('Use cases'!$K$2:$K$6000,"*NEW: RiskDisclosure,*")+COUNTIF('Use cases'!$K$2:$K$6000,"*NEW: RiskDisclosure")+COUNTIF('Use cases'!$K$2:$K$6000,"*NEW: RiskDisclosure *") -> 10 | C26: IV-01, IV-02, IV-03
A27: MoneyBackRoute | B27: =COUNTIF('Use cases'!$K$2:$K$6000,"*NEW: MoneyBackRoute,*")+COUNTIF('Use cases'!$K$2:$K$6000,"*NEW: MoneyBackRoute")+COUNTIF('Use cases'!$K$2:$K$6000,"*NEW: MoneyBackRoute *") -> 10 | C27: BE-03
A28: AddressPicker | B28: =COUNTIF('Use cases'!$K$2:$K$6000,"*NEW: AddressPicker,*")+COUNTIF('Use cases'!$K$2:$K$6000,"*NEW: AddressPicker")+COUNTIF('Use cases'!$K$2:$K$6000,"*NEW: AddressPicker *") -> 9 | C28: QC-01, QC-02, SB-04, SH-03, SH-04, SH-06, SH-07
A29: MemoryList | B29: =COUNTIF('Use cases'!$K$2:$K$6000,"*NEW: MemoryList,*")+COUNTIF('Use cases'!$K$2:$K$6000,"*NEW: MemoryList")+COUNTIF('Use cases'!$K$2:$K$6000,"*NEW: MemoryList *") -> 8 | C29: BS-01, EN-04, EN-06
A30: ReferralCard | B30: =COUNTIF('Use cases'!$K$2:$K$6000,"*NEW: ReferralCard,*")+COUNTIF('Use cases'!$K$2:$K$6000,"*NEW: ReferralCard")+COUNTIF('Use cases'!$K$2:$K$6000,"*NEW: ReferralCard *") -> 8 | C30: EN-05
A31: StatementCard | B31: =COUNTIF('Use cases'!$K$2:$K$6000,"*NEW: StatementCard,*")+COUNTIF('Use cases'!$K$2:$K$6000,"*NEW: StatementCard")+COUNTIF('Use cases'!$K$2:$K$6000,"*NEW: StatementCard *") -> 8 | C31: BS-01, BS-03
A32: CardholderList | B32: =COUNTIF('Use cases'!$K$2:$K$6000,"*NEW: CardholderList,*")+COUNTIF('Use cases'!$K$2:$K$6000,"*NEW: CardholderList")+COUNTIF('Use cases'!$K$2:$K$6000,"*NEW: CardholderList *") -> 8 | C32: BS-04, BS-08
A33: EarnTracker | B33: =COUNTIF('Use cases'!$K$2:$K$6000,"*NEW: EarnTracker,*")+COUNTIF('Use cases'!$K$2:$K$6000,"*NEW: EarnTracker")+COUNTIF('Use cases'!$K$2:$K$6000,"*NEW: EarnTracker *") -> 7 | C33: SH-05
A34: HoldingsCard | B34: =COUNTIF('Use cases'!$K$2:$K$6000,"*NEW: HoldingsCard,*")+COUNTIF('Use cases'!$K$2:$K$6000,"*NEW: HoldingsCard")+COUNTIF('Use cases'!$K$2:$K$6000,"*NEW: HoldingsCard *") -> 7 | C34: IV-01, IV-02, IV-03
A35: BalanceCard | B35: =COUNTIF('Use cases'!$K$2:$K$6000,"*NEW: BalanceCard,*")+COUNTIF('Use cases'!$K$2:$K$6000,"*NEW: BalanceCard")+COUNTIF('Use cases'!$K$2:$K$6000,"*NEW: BalanceCard *") -> 7 | C35: BS-02, BS-06
A36: SpendBreakdown | B36: =COUNTIF('Use cases'!$K$2:$K$6000,"*NEW: SpendBreakdown,*")+COUNTIF('Use cases'!$K$2:$K$6000,"*NEW: SpendBreakdown")+COUNTIF('Use cases'!$K$2:$K$6000,"*NEW: SpendBreakdown *") -> 7 | C36: BS-02, BS-03, BS-06, BS-08
A37: MenuCard | B37: =COUNTIF('Use cases'!$K$2:$K$6000,"*NEW: MenuCard,*")+COUNTIF('Use cases'!$K$2:$K$6000,"*NEW: MenuCard")+COUNTIF('Use cases'!$K$2:$K$6000,"*NEW: MenuCard *") -> 6 | C37: DN-01, DN-02, QC-03 | D37: MenuItemOptions
A38: VariantPicker | B38: =COUNTIF('Use cases'!$K$2:$K$6000,"*NEW: VariantPicker,*")+COUNTIF('Use cases'!$K$2:$K$6000,"*NEW: VariantPicker")+COUNTIF('Use cases'!$K$2:$K$6000,"*NEW: VariantPicker *") -> 6 | C38: SH-01, SH-06, SH-07
A39: FxRate | B39: =COUNTIF('Use cases'!$K$2:$K$6000,"*NEW: FxRate,*")+COUNTIF('Use cases'!$K$2:$K$6000,"*NEW: FxRate")+COUNTIF('Use cases'!$K$2:$K$6000,"*NEW: FxRate *") -> 6 | C39: TD-02
A40: EsimPlan | B40: =COUNTIF('Use cases'!$K$2:$K$6000,"*NEW: EsimPlan,*")+COUNTIF('Use cases'!$K$2:$K$6000,"*NEW: EsimPlan")+COUNTIF('Use cases'!$K$2:$K$6000,"*NEW: EsimPlan *") -> 6 | C40: TD-04
...

Sheet Markets
A1: Market | B1: Currency | C1: Number and date format | D1: How a payment is confirmed | E1: Automatic card payment is called | F1: Tax on fares | G1: Flight disruption rule | H1: Amounts set in law? | I1: Week starts | J1: Languages | K1: To confirm with the bank
A2: United Kingdom | B2: GBP £ | C2: en-GB · 1,234.50 · Fri 16 Oct | D2: Face ID in the bank app | E2: Direct Debit | F2: No VAT on flights; Air Passenger Duty in fares | G2: UK261 | H2: Yes: £220, £350, £520 by distance | I2: Monday | J2: English | K2: Point value; claims process
A3: Eurozone | B3: EUR € | C3: en-IE for English; local languages later | D3: Face ID in the bank app (strong customer authentication) | E3: direct debit | F3: International flights usually VAT-exempt; local ticket taxes (to confirm) | G3: EU261 (reform agreed June 2026, adoption pending) | H3: Yes: €250, €400, €600 by distance | I3: Monday | J3: English first; German, French, Spanish, Italian, Dutch to add | K3: Point value; which languages first
A4: India | B4: INR ₹ | C4: en-IN · lakh grouping (1,00,000) · Fri 16 Oct | D4: One-time code (other methods allowed under RBI authentication rules; to confirm per bank) | E4: auto-debit | F4: GST; GST invoice needs company GSTIN | G4: DGCA CAR Section 3, Series M, Part IV | H4: Yes, set by DGCA; legal team to confirm current amounts | I4: Sunday | J4: English first; Hindi next | K4: Point value; authentication method; EMI terms
A5: UAE | B5: AED | C5: en-AE and ar-AE (right to left) | D5: Face ID in the bank app | E5: direct debit | F5: VAT zero-rated on international flights (to confirm) | G5: Airline policy (legal team to confirm any GCAA rule) | H5: Legal team to confirm | I5: Monday | J5: English and Arabic (Arabic copy needs native sign-off) | K5: Point value; Arabic copy
A6: Singapore | B6: SGD S$ | C6: en-SG · 1,234.50 | D6: Face ID in the bank app | E6: GIRO | F6: GST zero-rated on international flights; airport levies | G6: Airline policy; no statutory scheme | H6: No | I6: Sunday | J6: English | K6: Point value
A7: Malaysia | B7: MYR RM | C7: en-MY · 1,234.50 | D7: Approval in the bank's app | E7: auto-debit | F7: No SST on fares (to confirm); departure levy on international flights | G7: Malaysian Aviation Consumer Protection Code 2016, enforced by CAAM | H7: Legal team to confirm | I7: Monday | J7: English first; Malay next | K7: Point value; app approval flow
A9: These settings live in the kit as data (Markets card). A new market is one more row here and one more entry in the kit; no redesign.

Sheet Grammar
A1: The grammar
A3: Stage | B3: Means | D3: Most common exceptions | G3: Most common constraints
A4: Discover | B4: Before they know what they want | D4: Cancelled by supplier | E4: 20 | G4: Plans changed | H4: 37
A5: Search | B5: Looking for options | D5: Payment declined | E5: 18 | G5: Enough points | H5: 32
A6: Choose | B6: Comparing and deciding | D6: Sold out | E6: 13 | G6: Not enough points | H6: 21
A7: Pay | B7: Money or points move | D7: Price rose | E7: 12 | G7: Date fixed | H7: 21
A8: Add-ons | B8: Extras on top of the main thing | D8: Not eligible | E8: 10 | G8: Unhappy | H8: 19
A9: Before | B9: Bought or booked, not yet used | D9: Supplier down | E9: 9 | G9: Premium | H9: 18
A10: During | B10: Using it now | D10: Fraud flag | E10: 8 | G10: Feedback | H10: 16
A11: Problem | B11: Something went wrong | D11: Not enough points | E11: 7 | G11: Accessibility | H11: 15
A12: After | B12: Done; refunds, reviews, repeats | D12: Declined | E12: 6 | G12: Card benefit | H12: 14
A13: Account | B13: The bank and points side | D13: Code rejected | E13: 6 | G13: Travelling with kids | H13: 13
D14: Late delivery | E14: 6 | G14: Changed mind | H14: 13
D15: Short of points | E15: 5 | G15: Abroad | H15: 13
D16: Wrong item | E16: 4 | G16: Business | H16: 12
D17: Expired | E17: 4 | G17: Budget in points | H17: 11
D18: No ticket yet | E18: 3 | G18: Group | H18: 9
D19: No-show | E19: 3 | G19: Points | H19: 9
D20: No supply | E20: 3 | G20: Delivered | H20: 9
D21: Damaged | E21: 3 | G21: Trip booked | H21: 8
D22: Not as described | E22: 3 | G22: Business card | H22: 8
D23: Fraud | E23: 3 | G23: Dates fixed | H23: 7
D24: Not allowed | E24: 3 | G24: Before travel | H24: 7
D25: Points expired | E25: 3 | G25: Landed | H25: 7
... D43: Missed each other | E43: 2 | G43: Repeat | H43: 5
